Workbook

Sheet Haq — Three-scenario comparison
A1: Haq — Three-scenario comparison
A2: Haq — Forecast dashboard · Main Scenario
A4: Variable / dimension | B4: Value | C4: Value > Conservative | D4: Value > Growth
A5: Haq Sustained break-even month | B5: 16 | D5: 10
A6: Haq First negative cash month | B6: =IF(AND('Model inputs'!B561="",'Model inputs'!B562="",'Model inputs'!B563="",'Model inputs'!B564="",'Model inputs'!B565="",'Model inputs'!B566="",'Model inputs'!B567="",'Model inputs'!B568="",'Model inputs'!B569="",'Model inputs'!B570="",'Model inputs'!B571="",'Model inputs'!B572="",'Model inputs'!B573="",'Model inputs'!B574="",'Model inputs'!B575="",'Model inputs'!B576="",'Model inputs'!B577="",'Model inputs'!B578="",'Model inputs'!B579="",'Model inputs'!B580="",'Model inputs'!B581="",'Model inputs'!B582="",'Model inputs'!B583="",'Model inputs'!B584="",'Model inputs'!B585="",'Model inputs'!B586="",'Model inputs'!B587="",'Model inputs'!B588="",'Model inputs'!B589="",'Model inputs'!B590="",'Model inputs'!B591="",'Model inputs'!B592="",'Model inputs'!B593="",'Model inputs'!B594=""),"",MIN('Model inputs'!B561,'Model inputs'!B562,'Model inputs'!B563,'Model inputs'!B564,'Model inputs'!B565,'Model inputs'!B566,'Model inputs'!B567,'Model inputs'!B568,'Model inputs'!B569,'Model inputs'!B570,'Model inputs'!B571,'Model inputs'!B572,'Model inputs'!B573,'Model inputs'!B574,'Model inputs'!B575,'Model inputs'!B576,'Model inputs'!B577,'Model inputs'!B578,'Model inputs'!B579,'Model inputs'!B580,'Model inputs'!B581,'Model inputs'!B582,'Model inputs'!B583,'Model inputs'!B584,'Model inputs'!B585,'Model inputs'!B586,'Model inputs'!B587,'Model inputs'!B588,'Model inputs'!B589,'Model inputs'!B590,'Model inputs'!B591,'Model inputs'!B592,'Model inputs'!B593,'Model inputs'!B594)) | C6: =IF(AND('Model inputs'!B629="",'Model inputs'!B630="",'Model inputs'!B631="",'Model inputs'!B632="",'Model inputs'!B633="",'Model inputs'!B634="",'Model inputs'!B635="",'Model inputs'!B636="",'Model inputs'!B637="",'Model inputs'!B638="",'Model inputs'!B639="",'Model inputs'!B640="",'Model inputs'!B641="",'Model inputs'!B642="",'Model inputs'!B643="",'Model inputs'!B644="",'Model inputs'!B645="",'Model inputs'!B646="",'Model inputs'!B647="",'Model inputs'!B648="",'Model inputs'!B649="",'Model inputs'!B650="",'Model inputs'!B651="",'Model inputs'!B652="",'Model inputs'!B653="",'Model inputs'!B654="",'Model inputs'!B655="",'Model inputs'!B656="",'Model inputs'!B657="",'Model inputs'!B658="",'Model inputs'!B659="",'Model inputs'!B660="",'Model inputs'!B661="",'Model inputs'!B662=""),"",MIN('Model inputs'!B629,'Model inputs'!B630,'Model inputs'!B631,'Model inputs'!B632,'Model inputs'!B633,'Model inputs'!B634,'Model inputs'!B635,'Model inputs'!B636,'Model inputs'!B637,'Model inputs'!B638,'Model inputs'!B639,'Model inputs'!B640,'Model inputs'!B641,'Model inputs'!B642,'Model inputs'!B643,'Model inputs'!B644,'Model inputs'!B645,'Model inputs'!B646,'Model inputs'!B647,'Model inputs'!B648,'Model inputs'!B649,'Model inputs'!B650,'Model inputs'!B651,'Model inputs'!B652,'Model inputs'!B653,'Model inputs'!B654,'Model inputs'!B655,'Model inputs'!B656,'Model inputs'!B657,'Model inputs'!B658,'Model inputs'!B659,'Model inputs'!B660,'Model inputs'!B661,'Model inputs'!B662)) -> 11 | D6: =IF(AND('Model inputs'!B697="",'Model inputs'!B698="",'Model inputs'!B699="",'Model inputs'!B700="",'Model inputs'!B701="",'Model inputs'!B702="",'Model inputs'!B703="",'Model inputs'!B704="",'Model inputs'!B705="",'Model inputs'!B706="",'Model inputs'!B707="",'Model inputs'!B708="",'Model inputs'!B709="",'Model inputs'!B710="",'Model inputs'!B711="",'Model inputs'!B712="",'Model inputs'!B713="",'Model inputs'!B714="",'Model inputs'!B715="",'Model inputs'!B716="",'Model inputs'!B717="",'Model inputs'!B718="",'Model inputs'!B719="",'Model inputs'!B720="",'Model inputs'!B721="",'Model inputs'!B722="",'Model inputs'!B723="",'Model inputs'!B724="",'Model inputs'!B725="",'Model inputs'!B726="",'Model inputs'!B727="",'Model inputs'!B728="",'Model inputs'!B729="",'Model inputs'!B730=""),"",MIN('Model inputs'!B697,'Model inputs'!B698,'Model inputs'!B699,'Model inputs'!B700,'Model inputs'!B701,'Model inputs'!B702,'Model inputs'!B703,'Model inputs'!B704,'Model inputs'!B705,'Model inputs'!B706,'Model inputs'!B707,'Model inputs'!B708,'Model inputs'!B709,'Model inputs'!B710,'Model inputs'!B711,'Model inputs'!B712,'Model inputs'!B713,'Model inputs'!B714,'Model inputs'!B715,'Model inputs'!B716,'Model inputs'!B717,'Model inputs'!B718,'Model inputs'!B719,'Model inputs'!B720,'Model inputs'!B721,'Model inputs'!B722,'Model inputs'!B723,'Model inputs'!B724,'Model inputs'!B725,'Model inputs'!B726,'Model inputs'!B727,'Model inputs'!B728,'Model inputs'!B729,'Model inputs'!B730))
A7: Haq Minimum cash | B7: =MIN('Model inputs'!L12,'Model inputs'!M12,'Model inputs'!N12,'Model inputs'!O12,'Model inputs'!P12,'Model inputs'!Q12,'Model inputs'!R12,'Model inputs'!S12,'Model inputs'!T12,'Model inputs'!U12,'Model inputs'!V12,'Model inputs'!W12,'Model inputs'!X12,'Model inputs'!Y12,'Model inputs'!Z12,'Model inputs'!AA12,'Model inputs'!AB12,'Model inputs'!AC12,'Model inputs'!AD12,'Model inputs'!AE12,'Model inputs'!AF12,'Model inputs'!AG12,'Model inputs'!AH12,'Model inputs'!AI12) -> 810268.19 | C7: =MIN('Model inputs'!L14,'Model inputs'!M14,'Model inputs'!N14,'Model inputs'!O14,'Model inputs'!P14,'Model inputs'!Q14,'Model inputs'!R14,'Model inputs'!S14,'Model inputs'!T14,'Model inputs'!U14,'Model inputs'!V14,'Model inputs'!W14,'Model inputs'!X14,'Model inputs'!Y14,'Model inputs'!Z14,'Model inputs'!AA14,'Model inputs'!AB14,'Model inputs'!AC14,'Model inputs'!AD14,'Model inputs'!AE14,'Model inputs'!AF14,'Model inputs'!AG14,'Model inputs'!AH14,'Model inputs'!AI14) -> -2467217.3 | D7: =MIN('Model inputs'!L13,'Model inputs'!M13,'Model inputs'!N13,'Model inputs'!O13,'Model inputs'!P13,'Model inputs'!Q13,'Model inputs'!R13,'Model inputs'!S13,'Model inputs'!T13,'Model inputs'!U13,'Model inputs'!V13,'Model inputs'!W13,'Model inputs'!X13,'Model inputs'!Y13,'Model inputs'!Z13,'Model inputs'!AA13,'Model inputs'!AB13,'Model inputs'!AC13,'Model inputs'!AD13,'Model inputs'!AE13,'Model inputs'!AF13,'Model inputs'!AG13,'Model inputs'!AH13,'Model inputs'!AI13) -> 1400843
A8: Haq Additional minimum funding | B8: =MAX(-MIN('Model inputs'!L12,'Model inputs'!M12,'Model inputs'!N12,'Model inputs'!O12,'Model inputs'!P12,'Model inputs'!Q12,'Model inputs'!R12,'Model inputs'!S12,'Model inputs'!T12,'Model inputs'!U12,'Model inputs'!V12,'Model inputs'!W12,'Model inputs'!X12,'Model inputs'!Y12,'Model inputs'!Z12,'Model inputs'!AA12,'Model inputs'!AB12,'Model inputs'!AC12,'Model inputs'!AD12,'Model inputs'!AE12,'Model inputs'!AF12,'Model inputs'!AG12,'Model inputs'!AH12,'Model inputs'!AI12),0) -> 0 | C8: =MAX(-MIN('Model inputs'!L14,'Model inputs'!M14,'Model inputs'!N14,'Model inputs'!O14,'Model inputs'!P14,'Model inputs'!Q14,'Model inputs'!R14,'Model inputs'!S14,'Model inputs'!T14,'Model inputs'!U14,'Model inputs'!V14,'Model inputs'!W14,'Model inputs'!X14,'Model inputs'!Y14,'Model inputs'!Z14,'Model inputs'!AA14,'Model inputs'!AB14,'Model inputs'!AC14,'Model inputs'!AD14,'Model inputs'!AE14,'Model inputs'!AF14,'Model inputs'!AG14,'Model inputs'!AH14,'Model inputs'!AI14),0) -> 2467217.3 | D8: =MAX(-MIN('Model inputs'!L13,'Model inputs'!M13,'Model inputs'!N13,'Model inputs'!O13,'Model inputs'!P13,'Model inputs'!Q13,'Model inputs'!R13,'Model inputs'!S13,'Model inputs'!T13,'Model inputs'!U13,'Model inputs'!V13,'Model inputs'!W13,'Model inputs'!X13,'Model inputs'!Y13,'Model inputs'!Z13,'Model inputs'!AA13,'Model inputs'!AB13,'Model inputs'!AC13,'Model inputs'!AD13,'Model inputs'!AE13,'Model inputs'!AF13,'Model inputs'!AG13,'Model inputs'!AH13,'Model inputs'!AI13),0) -> 0
A9: Haq Funding with safety reserve | B9: =MAX('Model inputs'!AJ63-MIN('Model inputs'!L12,'Model inputs'!M12,'Model inputs'!N12,'Model inputs'!O12,'Model inputs'!P12,'Model inputs'!Q12,'Model inputs'!R12,'Model inputs'!S12,'Model inputs'!T12,'Model inputs'!U12,'Model inputs'!V12,'Model inputs'!W12,'Model inputs'!X12,'Model inputs'!Y12,'Model inputs'!Z12,'Model inputs'!AA12,'Model inputs'!AB12,'Model inputs'!AC12,'Model inputs'!AD12,'Model inputs'!AE12,'Model inputs'!AF12,'Model inputs'!AG12,'Model inputs'!AH12,'Model inputs'!AI12),0) -> 189731.81 | C9: =MAX('Model inputs'!AJ175-MIN('Model inputs'!L14,'Model inputs'!M14,'Model inputs'!N14,'Model inputs'!O14,'Model inputs'!P14,'Model inputs'!Q14,'Model inputs'!R14,'Model inputs'!S14,'Model inputs'!T14,'Model inputs'!U14,'Model inputs'!V14,'Model inputs'!W14,'Model inputs'!X14,'Model inputs'!Y14,'Model inputs'!Z14,'Model inputs'!AA14,'Model inputs'!AB14,'Model inputs'!AC14,'Model inputs'!AD14,'Model inputs'!AE14,'Model inputs'!AF14,'Model inputs'!AG14,'Model inputs'!AH14,'Model inputs'!AI14),0) -> 3467217.3 | D9: =MAX('Model inputs'!AJ119-MIN('Model inputs'!L13,'Model inputs'!M13,'Model inputs'!N13,'Model inputs'!O13,'Model inputs'!P13,'Model inputs'!Q13,'Model inputs'!R13,'Model inputs'!S13,'Model inputs'!T13,'Model inputs'!U13,'Model inputs'!V13,'Model inputs'!W13,'Model inputs'!X13,'Model inputs'!Y13,'Model inputs'!Z13,'Model inputs'!AA13,'Model inputs'!AB13,'Model inputs'!AC13,'Model inputs'!AD13,'Model inputs'!AE13,'Model inputs'!AF13,'Model inputs'!AG13,'Model inputs'!AH13,'Model inputs'!AI13),0) -> 0
A10: Haq Extra acquisition spend | B10: =SUM('Model inputs'!L6,'Model inputs'!M6,'Model inputs'!N6,'Model inputs'!O6,'Model inputs'!P6,'Model inputs'!Q6,'Model inputs'!R6,'Model inputs'!S6,'Model inputs'!T6,'Model inputs'!U6,'Model inputs'!V6,'Model inputs'!W6,'Model inputs'!X6,'Model inputs'!Y6,'Model inputs'!Z6,'Model inputs'!AA6,'Model inputs'!AB6,'Model inputs'!AC6,'Model inputs'!AD6,'Model inputs'!AE6,'Model inputs'!AF6,'Model inputs'!AG6,'Model inputs'!AH6,'Model inputs'!AI6) -> 1227535.7 | C10: =SUM('Model inputs'!L8,'Model inputs'!M8,'Model inputs'!N8,'Model inputs'!O8,'Model inputs'!P8,'Model inputs'!Q8,'Model inputs'!R8,'Model inputs'!S8,'Model inputs'!T8,'Model inputs'!U8,'Model inputs'!V8,'Model inputs'!W8,'Model inputs'!X8,'Model inputs'!Y8,'Model inputs'!Z8,'Model inputs'!AA8,'Model inputs'!AB8,'Model inputs'!AC8,'Model inputs'!AD8,'Model inputs'!AE8,'Model inputs'!AF8,'Model inputs'!AG8,'Model inputs'!AH8,'Model inputs'!AI8) -> 50000 | D10: =SUM('Model inputs'!L7,'Model inputs'!M7,'Model inputs'!N7,'Model inputs'!O7,'Model inputs'!P7,'Model inputs'!Q7,'Model inputs'!R7,'Model inputs'!S7,'Model inputs'!T7,'Model inputs'!U7,'Model inputs'!V7,'Model inputs'!W7,'Model inputs'!X7,'Model inputs'!Y7,'Model inputs'!Z7,'Model inputs'!AA7,'Model inputs'!AB7,'Model inputs'!AC7,'Model inputs'!AD7,'Model inputs'!AE7,'Model inputs'!AF7,'Model inputs'!AG7,'Model inputs'!AH7,'Model inputs'!AI7) -> 12210692
A11: Haq Gross CSC acquisition demand | B11: =SUM('Model inputs'!L9,'Model inputs'!M9,'Model inputs'!N9,'Model inputs'!O9,'Model inputs'!P9,'Model inputs'!Q9,'Model inputs'!R9,'Model inputs'!S9,'Model inputs'!T9,'Model inputs'!U9,'Model inputs'!V9,'Model inputs'!W9,'Model inputs'!X9,'Model inputs'!Y9,'Model inputs'!Z9,'Model inputs'!AA9,'Model inputs'!AB9,'Model inputs'!AC9,'Model inputs'!AD9,'Model inputs'!AE9,'Model inputs'!AF9,'Model inputs'!AG9,'Model inputs'!AH9,'Model inputs'!AI9)*'Model inputs'!AJ25 -> 2148871.7 | C11: =SUM('Model inputs'!L11,'Model inputs'!M11,'Model inputs'!N11,'Model inputs'!O11,'Model inputs'!P11,'Model inputs'!Q11,'Model inputs'!R11,'Model inputs'!S11,'Model inputs'!T11,'Model inputs'!U11,'Model inputs'!V11,'Model inputs'!W11,'Model inputs'!X11,'Model inputs'!Y11,'Model inputs'!Z11,'Model inputs'!AA11,'Model inputs'!AB11,'Model inputs'!AC11,'Model inputs'!AD11,'Model inputs'!AE11,'Model inputs'!AF11,'Model inputs'!AG11,'Model inputs'!AH11,'Model inputs'!AI11)*'Model inputs'!AJ137 -> 368703.74 | D11: =SUM('Model inputs'!L10,'Model inputs'!M10,'Model inputs'!N10,'Model inputs'!O10,'Model inputs'!P10,'Model inputs'!Q10,'Model inputs'!R10,'Model inputs'!S10,'Model inputs'!T10,'Model inputs'!U10,'Model inputs'!V10,'Model inputs'!W10,'Model inputs'!X10,'Model inputs'!Y10,'Model inputs'!Z10,'Model inputs'!AA10,'Model inputs'!AB10,'Model inputs'!AC10,'Model inputs'!AD10,'Model inputs'!AE10,'Model inputs'!AF10,'Model inputs'!AG10,'Model inputs'!AH10,'Model inputs'!AI10)*'Model inputs'!AJ81 -> 13227179

Sheet Model inputs
A1: Model inputs
A2: Integration values are aggregated snapshots; raw source records are not included.
A4: Variables
A5: Variable / segment | B5: 2026-01 | C5: 2026-02 | D5: 2026-03 | E5: 2026-04 | F5: 2026-05 | G5: 2026-06 | H5: 2026-07 | I5: 2026-08 | J5: 2026-09 | K5: 2026-10 | L5: 2026-11 | M5: 2026-12 | N5: 2027-01 | O5: 2027-02 | P5: 2027-03 | Q5: 2027-04 | R5: 2027-05 | S5: 2027-06 | T5: 2027-07 | U5: 2027-08 | V5: 2027-09 | W5: 2027-10 | X5: 2027-11 | Y5: 2027-12 | Z5: 2028-01 | AA5: 2028-02 | AB5: 2028-03 | AC5: 2028-04 | AD5: 2028-05 | AE5: 2028-06 | AF5: 2028-07 | AG5: 2028-08 | AH5: 2028-09 | AI5: 2028-10 | AJ5: Value | AK5: Value
A6: Haq Acquisition top-up · Main Scenario | B6: =MAX('Model inputs'!B9*'Model inputs'!AJ25-'Model inputs'!AJ65*'Model inputs'!AJ64,0) -> 0 | C6: =MAX('Model inputs'!C9*'Model inputs'!AJ25-'Model inputs'!AJ65*'Model inputs'!AJ64,0) -> 0 | D6: =MAX('Model inputs'!D9*'Model inputs'!AJ25-'Model inputs'!AJ65*'Model inputs'!AJ64,0) -> 0 | E6: =MAX('Model inputs'!E9*'Model inputs'!AJ25-'Model inputs'!AJ65*'Model inputs'!AJ64,0) -> 0 | F6: =MAX('Model inputs'!F9*'Model inputs'!AJ25-'Model inputs'!AJ65*'Model inputs'!AJ64,0) -> 0 | G6: =MAX('Model inputs'!G9*'Model inputs'!AJ25-'Model inputs'!AJ65*'Model inputs'!AJ64,0) -> 0 | H6: =MAX('Model inputs'!H9*'Model inputs'!AJ25-'Model inputs'!AJ65*'Model inputs'!AJ64,0) -> 0 | I6: =MAX('Model inputs'!I9*'Model inputs'!AJ25-'Model inputs'!AJ65*'Model inputs'!AJ64,0) -> 0 | J6: =MAX('Model inputs'!J9*'Model inputs'!AJ25-'Model inputs'!AJ65*'Model inputs'!AJ64,0) -> 0 | K6: =MAX('Model inputs'!K9*'Model inputs'!AJ25-'Model inputs'!AJ65*'Model inputs'!AJ64,0) -> 0 | L6: =MAX('Model inputs'!L9*'Model inputs'!AJ25-'Model inputs'!AJ65*'Model inputs'!AJ64,0) -> 0 | M6: =MAX('Model inputs'!M9*'Model inputs'!AJ25-'Model inputs'!AJ65*'Model inputs'!AJ64,0) -> 0 | N6: =MAX('Model inputs'!N9*'Model inputs'!AJ25-'Model inputs'!AJ65*'Model inputs'!AJ64,0) -> 0 | O6: =MAX('Model inputs'!O9*'Model inputs'!AJ25-'Model inputs'!AJ65*'Model inputs'!AJ64,0) -> 50000 | P6: =MAX('Model inputs'!P9*'Model inputs'!AJ25-'Model inputs'!AJ65*'Model inputs'!AJ64,0) -> 0 | Q6: =MAX('Model inputs'!Q9*'Model inputs'!AJ25-'Model inputs'!AJ65*'Model inputs'!AJ64,0) -> 0 | R6: =MAX('Model inputs'!R9*'Model inputs'!AJ25-'Model inputs'!AJ65*'Model inputs'!AJ64,0) -> 0 | S6: =MAX('Model inputs'!S9*'Model inputs'!AJ25-'Model inputs'!AJ65*'Model inputs'!AJ64,0) -> 0 | T6: =MAX('Model inputs'!T9*'Model inputs'!AJ25-'Model inputs'!AJ65*'Model inputs'!AJ64,0) -> 0 | U6: =MAX('Model inputs'!U9*'Model inputs'!AJ25-'Model inputs'!AJ65*'Model inputs'!AJ64,0) -> 0 | V6: =MAX('Model inputs'!V9*'Model inputs'!AJ25-'Model inputs'!AJ65*'Model inputs'!AJ64,0) -> 0 | W6: =MAX('Model inputs'!W9*'Model inputs'!AJ25-'Model inputs'!AJ65*'Model inputs'!AJ64,0) -> 3200.3976 | X6: =MAX('Model inputs'!X9*'Model inputs'!AJ25-'Model inputs'!AJ65*'Model inputs'!AJ64,0) -> 11180.457 | Y6: =MAX('Model inputs'!Y9*'Model inputs'!AJ25-'Model inputs'!AJ65*'Model inputs'!AJ64,0) -> 20357.526 | Z6: =MAX('Model inputs'!Z9*'Model inputs'!AJ25-'Model inputs'!AJ65*'Model inputs'!AJ64,0) -> 30911.155 | AA6: =MAX('Model inputs'!AA9*'Model inputs'!AJ25-'Model inputs'!AJ65*'Model inputs'!AJ64,0) -> 43047.828 | AB6: =MAX('Model inputs'!AB9*'Model inputs'!AJ25-'Model inputs'!AJ65*'Model inputs'!AJ64,0) -> 57005.002 | AC6: =MAX('Model inputs'!AC9*'Model inputs'!AJ25-'Model inputs'!AJ65*'Model inputs'!AJ64,0) -> 73055.752 | AD6: =MAX('Model inputs'!AD9*'Model inputs'!AJ25-'Model inputs'!AJ65*'Model inputs'!AJ64,0) -> 91514.115 | AE6: =MAX('Model inputs'!AE9*'Model inputs'!AJ25-'Model inputs'!AJ65*'Model inputs'!AJ64,0) -> 112741.23 | AF6: =MAX('Model inputs'!AF9*'Model inputs'!AJ25-'Model inputs'!AJ65*'Model inputs'!AJ64,0) -> 137152.42 | AG6: =MAX('Model inputs'!AG9*'Model inputs'!AJ25-'Model inputs'!AJ65*'Model inputs'!AJ64,0) -> 165225.28 | AH6: =MAX('Model inputs'!AH9*'Model inputs'!AJ25-'Model inputs'!AJ65*'Model inputs'!AJ64,0) -> 197509.07 | AI6: =MAX('Model inputs'!AI9*'Model inputs'!AJ25-'Model inputs'!AJ65*'Model inputs'!AJ64,0) -> 234635.43
A7: Haq Acquisition top-up · Growth | B7: =MAX('Model inputs'!B10*'Model inputs'!AJ81-'Model inputs'!AJ121*'Model inputs'!AJ120,0) -> 0 | C7: =MAX('Model inputs'!C10*'Model inputs'!AJ81-'Model inputs'!AJ121*'Model inputs'!AJ120,0) -> 0 | D7: =MAX('Model inputs'!D10*'Model inputs'!AJ81-'Model inputs'!AJ121*'Model inputs'!AJ120,0) -> 0 | E7: =MAX('Model inputs'!E10*'Model inputs'!AJ81-'Model inputs'!AJ121*'Model inputs'!AJ120,0) -> 0 | F7: =MAX('Model inputs'!F10*'Model inputs'!AJ81-'Model inputs'!AJ121*'Model inputs'!AJ120,0) -> 0 | G7: =MAX('Model inputs'!G10*'Model inputs'!AJ81-'Model inputs'!AJ121*'Model inputs'!AJ120,0) -> 0 | H7: =MAX('Model inputs'!H10*'Model inputs'!AJ81-'Model inputs'!AJ121*'Model inputs'!AJ120,0) -> 0 | I7: =MAX('Model inputs'!I10*'Model inputs'!AJ81-'Model inputs'!AJ121*'Model inputs'!AJ120,0) -> 0 | J7: =MAX('Model inputs'!J10*'Model inputs'!AJ81-'Model inputs'!AJ121*'Model inputs'!AJ120,0) -> 0 | K7: =MAX('Model inputs'!K10*'Model inputs'!AJ81-'Model inputs'!AJ121*'Model inputs'!AJ120,0) -> 0 | L7: =MAX('Model inputs'!L10*'Model inputs'!AJ81-'Model inputs'!AJ121*'Model inputs'!AJ120,0) -> 0 | M7: =MAX('Model inputs'!M10*'Model inputs'!AJ81-'Model inputs'!AJ121*'Model inputs'!AJ120,0) -> 0 | N7: =MAX('Model inputs'!N10*'Model inputs'!AJ81-'Model inputs'!AJ121*'Model inputs'!AJ120,0) -> 0 | O7: =MAX('Model inputs'!O10*'Model inputs'!AJ81-'Model inputs'!AJ121*'Model inputs'!AJ120,0) -> 50000 | P7: =MAX('Model inputs'!P10*'Model inputs'!AJ81-'Model inputs'!AJ121*'Model inputs'!AJ120,0) -> 0 | Q7: =MAX('Model inputs'!Q10*'Model inputs'!AJ81-'Model inputs'!AJ121*'Model inputs'!AJ120,0) -> 0 | R7: =MAX('Model inputs'!R10*'Model inputs'!AJ81-'Model inputs'!AJ121*'Model inputs'!AJ120,0) -> 0 | S7: =MAX('Model inputs'!S10*'Model inputs'!AJ81-'Model inputs'!AJ121*'Model inputs'!AJ120,0) -> 11451.49 | T7: =MAX('Model inputs'!T10*'Model inputs'!AJ81-'Model inputs'!AJ121*'Model inputs'!AJ120,0) -> 28043.392 | U7: =MAX('Model inputs'!U10*'Model inputs'!AJ81-'Model inputs'!AJ121*'Model inputs'!AJ120,0) -> 49115.108 | V7: =MAX('Model inputs'!V10*'Model inputs'!AJ81-'Model inputs'!AJ121*'Model inputs'!AJ120,0) -> 75876.187 | W7: =MAX('Model inputs'!W10*'Model inputs'!AJ81-'Model inputs'!AJ121*'Model inputs'!AJ120,0) -> 109862.76 | X7: =MAX('Model inputs'!X10*'Model inputs'!AJ81-'Model inputs'!AJ121*'Model inputs'!AJ120,0) -> 153025.7 | Y7: =MAX('Model inputs'!Y10*'Model inputs'!AJ81-'Model inputs'!AJ121*'Model inputs'!AJ120,0) -> 207842.64 | Z7: =MAX('Model inputs'!Z10*'Model inputs'!AJ81-'Model inputs'!AJ121*'Model inputs'!AJ120,0) -> 277460.16 | AA7: =MAX('Model inputs'!AA10*'Model inputs'!AJ81-'Model inputs'!AJ121*'Model inputs'!AJ120,0) -> 365874.4 | AB7: =MAX('Model inputs'!AB10*'Model inputs'!AJ81-'Model inputs'!AJ121*'Model inputs'!AJ120,0) -> 478160.49 | AC7: =MAX('Model inputs'!AC10*'Model inputs'!AJ81-'Model inputs'!AJ121*'Model inputs'!AJ120,0) -> 620763.82 | AD7: =MAX('Model inputs'!AD10*'Model inputs'!AJ81-'Model inputs'!AJ121*'Model inputs'!AJ120,0) -> 801870.05 | AE7: =MAX('Model inputs'!AE10*'Model inputs'!AJ81-'Model inputs'!AJ121*'Model inputs'!AJ120,0) -> 1031875 | AF7: =MAX('Model inputs'!AF10*'Model inputs'!AJ81-'Model inputs'!AJ121*'Model inputs'!AJ120,0) -> 1323981.2 | AG7: =MAX('Model inputs'!AG10*'Model inputs'!AJ81-'Model inputs'!AJ121*'Model inputs'!AJ120,0) -> 1694956.1 | AH7: =MAX('Model inputs'!AH10*'Model inputs'!AJ81-'Model inputs'!AJ121*'Model inputs'!AJ120,0) -> 2166094.3 | AI7: =MAX('Model inputs'!AI10*'Model inputs'!AJ81-'Model inputs'!AJ121*'Model inputs'!AJ120,0) -> 2764439.7
A8: Haq Acquisition top-up · Conservative | B8: =MAX('Model inputs'!B11*'Model inputs'!AJ137-'Model inputs'!AJ177*'Model inputs'!AJ176,0) -> 0 | C8: =MAX('Model inputs'!C11*'Model inputs'!AJ137-'Model inputs'!AJ177*'Model inputs'!AJ176,0) -> 0 | D8: =MAX('Model inputs'!D11*'Model inputs'!AJ137-'Model inputs'!AJ177*'Model inputs'!AJ176,0) -> 0 | E8: =MAX('Model inputs'!E11*'Model inputs'!AJ137-'Model inputs'!AJ177*'Model inputs'!AJ176,0) -> 0 | F8: =MAX('Model inputs'!F11*'Model inputs'!AJ137-'Model inputs'!AJ177*'Model inputs'!AJ176,0) -> 0 | G8: =MAX('Model inputs'!G11*'Model inputs'!AJ137-'Model inputs'!AJ177*'Model inputs'!AJ176,0) -> 0 | H8: =MAX('Model inputs'!H11*'Model inputs'!AJ137-'Model inputs'!AJ177*'Model inputs'!AJ176,0) -> 0 | I8: =MAX('Model inputs'!I11*'Model inputs'!AJ137-'Model inputs'!AJ177*'Model inputs'!AJ176,0) -> 0 | J8: =MAX('Model inputs'!J11*'Model inputs'!AJ137-'Model inputs'!AJ177*'Model inputs'!AJ176,0) -> 0 | K8: =MAX('Model inputs'!K11*'Model inputs'!AJ137-'Model inputs'!AJ177*'Model inputs'!AJ176,0) -> 0 | L8: =MAX('Model inputs'!L11*'Model inputs'!AJ137-'Model inputs'!AJ177*'Model inputs'!AJ176,0) -> 0 | M8: =MAX('Model inputs'!M11*'Model inputs'!AJ137-'Model inputs'!AJ177*'Model inputs'!AJ176,0) -> 0 | N8: =MAX('Model inputs'!N11*'Model inputs'!AJ137-'Model inputs'!AJ177*'Model inputs'!AJ176,0) -> 0 | O8: =MAX('Model inputs'!O11*'Model inputs'!AJ137-'Model inputs'!AJ177*'Model inputs'!AJ176,0) -> 50000 | P8: =MAX('Model inputs'!P11*'Model inputs'!AJ137-'Model inputs'!AJ177*'Model inputs'!AJ176,0) -> 0 | Q8: =MAX('Model inputs'!Q11*'Model inputs'!AJ137-'Model inputs'!AJ177*'Model inputs'!AJ176,0) -> 0 | R8: =MAX('Model inputs'!R11*'Model inputs'!AJ137-'Model inputs'!AJ177*'Model inputs'!AJ176,0) -> 0 | S8: =MAX('Model inputs'!S11*'Model inputs'!AJ137-'Model inputs'!AJ177*'Model inputs'!AJ176,0) -> 0 | T8: =MAX('Model inputs'!T11*'Model inputs'!AJ137-'Model inputs'!AJ177*'Model inputs'!AJ176,0) -> 0 | U8: =MAX('Model inputs'!U11*'Model inputs'!AJ137-'Model inputs'!AJ177*'Model inputs'!AJ176,0) -> 0 | V8: =MAX('Model inputs'!V11*'Model inputs'!AJ137-'Model inputs'!AJ177*'Model inputs'!AJ176,0) -> 0 | W8: =MAX('Model inputs'!W11*'Model inputs'!AJ137-'Model inputs'!AJ177*'Model inputs'!AJ176,0) -> 0 | X8: =MAX('Model inputs'!X11*'Model inputs'!AJ137-'Model inputs'!AJ177*'Model inputs'!AJ176,0) -> 0 | Y8: =MAX('Model inputs'!Y11*'Model inputs'!AJ137-'Model inputs'!AJ177*'Model inputs'!AJ176,0) -> 0 | Z8: =MAX('Model inputs'!Z11*'Model inputs'!AJ137-'Model inputs'!AJ177*'Model inputs'!AJ176,0) -> 0 | AA8: =MAX('Model inputs'!AA11*'Model inputs'!AJ137-'Model inputs'!AJ177*'Model inputs'!AJ176,0) -> 0 | AB8: =MAX('Model inputs'!AB11*'Model inputs'!AJ137-'Model inputs'!AJ177*'Model inputs'!AJ176,0) -> 0 | AC8: =MAX('Model inputs'!AC11*'Model inputs'!AJ137-'Model inputs'!AJ177*'Model inputs'!AJ176,0) -> 0 | AD8: =MAX('Model inputs'!AD11*'Model inputs'!AJ137-'Model inputs'!AJ177*'Model inputs'!AJ176,0) -> 0 | AE8: =MAX('Model inputs'!AE11*'Model inputs'!AJ137-'Model inputs'!AJ177*'Model inputs'!AJ176,0) -> 0 | AF8: =MAX('Model inputs'!AF11*'Model inputs'!AJ137-'Model inputs'!AJ177*'Model inputs'!AJ176,0) -> 0 | AG8: =MAX('Model inputs'!AG11*'Model inputs'!AJ137-'Model inputs'!AJ177*'Model inputs'!AJ176,0) -> 0 | AH8: =MAX('Model inputs'!AH11*'Model inputs'!AJ137-'Model inputs'!AJ177*'Model inputs'!AJ176,0) -> 0 | AI8: =MAX('Model inputs'!AI11*'Model inputs'!AJ137-'Model inputs'!AJ177*'Model inputs'!AJ176,0) -> 0
A9: Haq CSC new operators · Main Scenario | B9: =IF(IF(IF(ISERROR('Model inputs'!B186='Model inputs'!AJ26),'Model inputs'!B186='Model inputs'!AJ26,IF(OR('Model inputs'!B186="",'Model inputs'!AJ26=""),"",'Model inputs'!B186='Model inputs'!AJ26))="",FALSE,IF(ISERROR('Model inputs'!B186='Model inputs'!AJ26),'Model inputs'!B186='Model inputs'!AJ26,IF(OR('Model inputs'!B186="",'Model inputs'!AJ26=""),"",'Model inputs'!B186='Model inputs'!AJ26))),IF('Model inputs'!AJ27="","",'Model inputs'!AJ27),IF(IF(IF(ISERROR('Model inputs'!B186>'Model inputs'!AJ26),'Model inputs'!B186>'Model inputs'!AJ26,IF(OR('Model inputs'!B186="",'Model inputs'!AJ26=""),"",'Model inputs'!B186>'Model inputs'!AJ26))="",FALSE,IF(ISERROR('Model inputs'!B186>'Model inputs'!AJ26),'Model inputs'!B186>'Model inputs'!AJ26,IF(OR('Model inputs'!B186="",'Model inputs'!AJ26=""),"",'Model inputs'!B186>'Model inputs'!AJ26))),0*'Model inputs'!AJ23,0)) -> 0 | C9: =IF(IF(IF(ISERROR('Model inputs'!C186='Model inputs'!AJ26),'Model inputs'!C186='Model inputs'!AJ26,IF(OR('Model inputs'!C186="",'Model inputs'!AJ26=""),"",'Model inputs'!C186='Model inputs'!AJ26))="",FALSE,IF(ISERROR('Model inputs'!C186='Model inputs'!AJ26),'Model inputs'!C186='Model inputs'!AJ26,IF(OR('Model inputs'!C186="",'Model inputs'!AJ26=""),"",'Model inputs'!C186='Model inputs'!AJ26))),IF('Model inputs'!AJ27="","",'Model inputs'!AJ27),IF(IF(IF(ISERROR('Model inputs'!C186>'Model inputs'!AJ26),'Model inputs'!C186>'Model inputs'!AJ26,IF(OR('Model inputs'!C186="",'Model inputs'!AJ26=""),"",'Model inputs'!C186>'Model inputs'!AJ26))="",FALSE,IF(ISERROR('Model inputs'!C186>'Model inputs'!AJ26),'Model inputs'!C186>'Model inputs'!AJ26,IF(OR('Model inputs'!C186="",'Model inputs'!AJ26=""),"",'Model inputs'!C186>'Model inputs'!AJ26))),'Model inputs'!B189*'Model inputs'!AJ23,0)) -> 0 | D9: =IF(IF(IF(ISERROR('Model inputs'!D186='Model inputs'!AJ26),'Model inputs'!D186='Model inputs'!AJ26,IF(OR('Model inputs'!D186="",'Model inputs'!AJ26=""),"",'Model inputs'!D186='Model inputs'!AJ26))="",FALSE,IF(ISERROR('Model inputs'!D186='Model inputs'!AJ26),'Model inputs'!D186='Model inputs'!AJ26,IF(OR('Model inputs'!D186="",'Model inputs'!AJ26=""),"",'Model inputs'!D186='Model inputs'!AJ26))),IF('Model inputs'!AJ27="","",'Model inputs'!AJ27),IF(IF(IF(ISERROR('Model inputs'!D186>'Model inputs'!AJ26),'Model inputs'!D186>'Model inputs'!AJ26,IF(OR('Model inputs'!D186="",'Model inputs'!AJ26=""),"",'Model inputs'!D186>'Model inputs'!AJ26))="",FALSE,IF(ISERROR('Model inputs'!D186>'Model inputs'!AJ26),'Model inputs'!D186>'Model inputs'!AJ26,IF(OR('Model inputs'!D186="",'Model inputs'!AJ26=""),"",'Model inputs'!D186>'Model inputs'!AJ26))),'Model inputs'!C189*'Model inputs'!AJ23,0)) -> 0 | E9: =IF(IF(IF(ISERROR('Model inputs'!E186='Model inputs'!AJ26),'Model inputs'!E186='Model inputs'!AJ26,IF(OR('Model inputs'!E186="",'Model inputs'!AJ26=""),"",'Model inputs'!E186='Model inputs'!AJ26))="",FALSE,IF(ISERROR('Model inputs'!E186='Model inputs'!AJ26),'Model inputs'!E186='Model inputs'!AJ26,IF(OR('Model inputs'!E186="",'Model inputs'!AJ26=""),"",'Model inputs'!E186='Model inputs'!AJ26))),IF('Model inputs'!AJ27="","",'Model inputs'!AJ27),IF(IF(IF(ISERROR('Model inputs'!E186>'Model inputs'!AJ26),'Model inputs'!E186>'Model inputs'!AJ26,IF(OR('Model inputs'!E186="",'Model inputs'!AJ26=""),"",'Model inputs'!E186>'Model inputs'!AJ26))="",FALSE,IF(ISERROR('Model inputs'!E186>'Model inputs'!AJ26),'Model inputs'!E186>'Model inputs'!AJ26,IF(OR('Model inputs'!E186="",'Model inputs'!AJ26=""),"",'Model inputs'!E186>'Model inputs'!AJ26))),'Model inputs'!D189*'Model inputs'!AJ23,0)) -> 0 | F9: =IF(IF(IF(ISERROR('Model inputs'!F186='Model inputs'!AJ26),'Model inputs'!F186='Model inputs'!AJ26,IF(OR('Model inputs'!F186="",'Model inputs'!AJ26=""),"",'Model inputs'!F186='Model inputs'!AJ26))="",FALSE,IF(ISERROR('Model inputs'!F186='Model inputs'!AJ26),'Model inputs'!F186='Model inputs'!AJ26,IF(OR('Model inputs'!F186="",'Model inputs'!AJ26=""),"",'Model inputs'!F186='Model inputs'!AJ26))),IF('Model inputs'!AJ27="","",'Model inputs'!AJ27),IF(IF(IF(ISERROR('Model inputs'!F186>'Model inputs'!AJ26),'Model inputs'!F186>'Model inputs'!AJ26,IF(OR('Model inputs'!F186="",'Model inputs'!AJ26=""),"",'Model inputs'!F186>'Model inputs'!AJ26))="",FALSE,IF(ISERROR('Model inputs'!F186>'Model inputs'!AJ26),'Model inputs'!F186>'Model inputs'!AJ26,IF(OR('Model inputs'!F186="",'Model inputs'!AJ26=""),"",'Model inputs'!F186>'Model inputs'!AJ26))),'Model inputs'!E189*'Model inputs'!AJ23,0)) -> 0 | G9: =IF(IF(IF(ISERROR('Model inputs'!G186='Model inputs'!AJ26),'Model inputs'!G186='Model inputs'!AJ26,IF(OR('Model inputs'!G186="",'Model inputs'!AJ26=""),"",'Model inputs'!G186='Model inputs'!AJ26))="",FALSE,IF(ISERROR('Model inputs'!G186='Model inputs'!AJ26),'Model inputs'!G186='Model inputs'!AJ26,IF(OR('Model inputs'!G186="",'Model inputs'!AJ26=""),"",'Model inputs'!G186='Model inputs'!AJ26))),IF('Model inputs'!AJ27="","",'Model inputs'!AJ27),IF(IF(IF(ISERROR('Model inputs'!G186>'Model inputs'!AJ26),'Model inputs'!G186>'Model inputs'!AJ26,IF(OR('Model inputs'!G186="",'Model inputs'!AJ26=""),"",'Model inputs'!G186>'Model inputs'!AJ26))="",FALSE,IF(ISERROR('Model inputs'!G186>'Model inputs'!AJ26),'Model inputs'!G186>'Model inputs'!AJ26,IF(OR('Model inputs'!G186="",'Model inputs'!AJ26=""),"",'Model inputs'!G186>'Model inputs'!AJ26))),'Model inputs'!F189*'Model inputs'!AJ23,0)) -> 0 | H9: =IF(IF(IF(ISERROR('Model inputs'!H186='Model inputs'!AJ26),'Model inputs'!H186='Model inputs'!AJ26,IF(OR('Model inputs'!H186="",'Model inputs'!AJ26=""),"",'Model inputs'!H186='Model inputs'!AJ26))="",FALSE,IF(ISERROR('Model inputs'!H186='Model inputs'!AJ26),'Model inputs'!H186='Model inputs'!AJ26,IF(OR('Model inputs'!H186="",'Model inputs'!AJ26=""),"",'Model inputs'!H186='Model inputs'!AJ26))),IF('Model inputs'!AJ27="","",'Model inputs'!AJ27),IF(IF(IF(ISERROR('Model inputs'!H186>'Model inputs'!AJ26),'Model inputs'!H186>'Model inputs'!AJ26,IF(OR('Model inputs'!H186="",'Model inputs'!AJ26=""),"",'Model inputs'!H186>'Model inputs'!AJ26))="",FALSE,IF(ISERROR('Model inputs'!H186>'Model inputs'!AJ26),'Model inputs'!H186>'Model inputs'!AJ26,IF(OR('Model inputs'!H186="",'Model inputs'!AJ26=""),"",'Model inputs'!H186>'Model inputs'!AJ26))),'Model inputs'!G189*'Model inputs'!AJ23,0)) -> 0 | I9: =IF(IF(IF(ISERROR('Model inputs'!I186='Model inputs'!AJ26),'Model inputs'!I186='Model inputs'!AJ26,IF(OR('Model inputs'!I186="",'Model inputs'!AJ26=""),"",'Model inputs'!I186='Model inputs'!AJ26))="",FALSE,IF(ISERROR('Model inputs'!I186='Model inputs'!AJ26),'Model inputs'!I186='Model inputs'!AJ26,IF(OR('Model inputs'!I186="",'Model inputs'!AJ26=""),"",'Model inputs'!I186='Model inputs'!AJ26))),IF('Model inputs'!AJ27="","",'Model inputs'!AJ27),IF(IF(IF(ISERROR('Model inputs'!I186>'Model inputs'!AJ26),'Model inputs'!I186>'Model inputs'!AJ26,IF(OR('Model inputs'!I186="",'Model inputs'!AJ26=""),"",'Model inputs'!I186>'Model inputs'!AJ26))="",FALSE,IF(ISERROR('Model inputs'!I186>'Model inputs'!AJ26),'Model inputs'!I186>'Model inputs'!AJ26,IF(OR('Model inputs'!I186="",'Model inputs'!AJ26=""),"",'Model inputs'!I186>'Model inputs'!AJ26))),'Model inputs'!H189*'Model inputs'!AJ23,0)) -> 0 | J9: =IF(IF(IF(ISERROR('Model inputs'!J186='Model inputs'!AJ26),'Model inputs'!J186='Model inputs'!AJ26,IF(OR('Model inputs'!J186="",'Model inputs'!AJ26=""),"",'Model inputs'!J186='Model inputs'!AJ26))="",FALSE,IF(ISERROR('Model inputs'!J186='Model inputs'!AJ26),'Model inputs'!J186='Model inputs'!AJ26,IF(OR('Model inputs'!J186="",'Model inputs'!AJ26=""),"",'Model inputs'!J186='Model inputs'!AJ26))),IF('Model inputs'!AJ27="","",'Model inputs'!AJ27),IF(IF(IF(ISERROR('Model inputs'!J186>'Model inputs'!AJ26),'Model inputs'!J186>'Model inputs'!AJ26,IF(OR('Model inputs'!J186="",'Model inputs'!AJ26=""),"",'Model inputs'!J186>'Model inputs'!AJ26))="",FALSE,IF(ISERROR('Model inputs'!J186>'Model inputs'!AJ26),'Model inputs'!J186>'Model inputs'!AJ26,IF(OR('Model inputs'!J186="",'Model inputs'!AJ26=""),"",'Model inputs'!J186>'Model inputs'!AJ26))),'Model inputs'!I189*'Model inputs'!AJ23,0)) -> 0 | K9: =IF(IF(IF(ISERROR('Model inputs'!K186='Model inputs'!AJ26),'Model inputs'!K186='Model inputs'!AJ26,IF(OR('Model inputs'!K186="",'Model inputs'!AJ26=""),"",'Model inputs'!K186='Model inputs'!AJ26))="",FALSE,IF(ISERROR('Model inputs'!K186='Model inputs'!AJ26),'Model inputs'!K186='Model inputs'!AJ26,IF(OR('Model inputs'!K186="",'Model inputs'!AJ26=""),"",'Model inputs'!K186='Model inputs'!AJ26))),IF('Model inputs'!AJ27="","",'Model inputs'!AJ27),IF(IF(IF(ISERROR('Model inputs'!K186>'Model inputs'!AJ26),'Model inputs'!K186>'Model inputs'!AJ26,IF(OR('Model inputs'!K186="",'Model inputs'!AJ26=""),"",'Model inputs'!K186>'Model inputs'!AJ26))="",FALSE,IF(ISERROR('Model inputs'!K186>'Model inputs'!AJ26),'Model inputs'!K186>'Model inputs'!AJ26,IF(OR('Model inputs'!K186="",'Model inputs'!AJ26=""),"",'Model inputs'!K186>'Model inputs'!AJ26))),'Model inputs'!J189*'Model inputs'!AJ23,0)) -> 0 | L9: =IF(IF(IF(ISERROR('Model inputs'!L186='Model inputs'!AJ26),'Model inputs'!L186='Model inputs'!AJ26,IF(OR('Model inputs'!L186="",'Model inputs'!AJ26=""),"",'Model inputs'!L186='Model inputs'!AJ26))="",FALSE,IF(ISERROR('Model inputs'!L186='Model inputs'!AJ26),'Model inputs'!L186='Model inputs'!AJ26,IF(OR('Model inputs'!L186="",'Model inputs'!AJ26=""),"",'Model inputs'!L186='Model inputs'!AJ26))),IF('Model inputs'!AJ27="","",'Model inputs'!AJ27),IF(IF(IF(ISERROR('Model inputs'!L186>'Model inputs'!AJ26),'Model inputs'!L186>'Model inputs'!AJ26,IF(OR('Model inputs'!L186="",'Model inputs'!AJ26=""),"",'Model inputs'!L186>'Model inputs'!AJ26))="",FALSE,IF(ISERROR('Model inputs'!L186>'Model inputs'!AJ26),'Model inputs'!L186>'Model inputs'!AJ26,IF(OR('Model inputs'!L186="",'Model inputs'!AJ26=""),"",'Model inputs'!L186>'Model inputs'!AJ26))),'Model inputs'!K189*'Model inputs'!AJ23,0)) -> 0 | M9: =IF(IF(IF(ISERROR('Model inputs'!M186='Model inputs'!AJ26),'Model inputs'!M186='Model inputs'!AJ26,IF(OR('Model inputs'!M186="",'Model inputs'!AJ26=""),"",'Model inputs'!M186='Model inputs'!AJ26))="",FALSE,IF(ISERROR('Model inputs'!M186='Model inputs'!AJ26),'Model inputs'!M186='Model inputs'!AJ26,IF(OR('Model inputs'!M186="",'Model inputs'!AJ26=""),"",'Model inputs'!M186='Model inputs'!AJ26))),IF('Model inputs'!AJ27="","",'Model inputs'!AJ27),IF(IF(IF(ISERROR('Model inputs'!M186>'Model inputs'!AJ26),'Model inputs'!M186>'Model inputs'!AJ26,IF(OR('Model inputs'!M186="",'Model inputs'!AJ26=""),"",'Model inputs'!M186>'Model inputs'!AJ26))="",FALSE,IF(ISERROR('Model inputs'!M186>'Model inputs'!AJ26),'Model inputs'!M186>'Model inputs'!AJ26,IF(OR('Model inputs'!M186="",'Model inputs'!AJ26=""),"",'Model inputs'!M186>'Model inputs'!AJ26))),'Model inputs'!L189*'Model inputs'!AJ23,0)) -> 0 | N9: =IF(IF(IF(ISERROR('Model inputs'!N186='Model inputs'!AJ26),'Model inputs'!N186='Model inputs'!AJ26,IF(OR('Model inputs'!N186="",'Model inputs'!AJ26=""),"",'Model inputs'!N186='Model inputs'!AJ26))="",FALSE,IF(ISERROR('Model inputs'!N186='Model inputs'!AJ26),'Model inputs'!N186='Model inputs'!AJ26,IF(OR('Model inputs'!N186="",'Model inputs'!AJ26=""),"",'Model inputs'!N186='Model inputs'!AJ26))),IF('Model inputs'!AJ27="","",'Model inputs'!AJ27),IF(IF(IF(ISERROR('Model inputs'!N186>'Model inputs'!AJ26),'Model inputs'!N186>'Model inputs'!AJ26,IF(OR('Model inputs'!N186="",'Model inputs'!AJ26=""),"",'Model inputs'!N186>'Model inputs'!AJ26))="",FALSE,IF(ISERROR('Model inputs'!N186>'Model inputs'!AJ26),'Model inputs'!N186>'Model inputs'!AJ26,IF(OR('Model inputs'!N186="",'Model inputs'!AJ26=""),"",'Model inputs'!N186>'Model inputs'!AJ26))),'Model inputs'!M189*'Model inputs'!AJ23,0)) -> 0 | O9: =IF(IF(IF(ISERROR('Model inputs'!O186='Model inputs'!AJ26),'Model inputs'!O186='Model inputs'!AJ26,IF(OR('Model inputs'!O186="",'Model inputs'!AJ26=""),"",'Model inputs'!O186='Model inputs'!AJ26))="",FALSE,IF(ISERROR('Model inputs'!O186='Model inputs'!AJ26),'Model inputs'!O186='Model inputs'!AJ26,IF(OR('Model inputs'!O186="",'Model inputs'!AJ26=""),"",'Model inputs'!O186='Model inputs'!AJ26))),IF('Model inputs'!AJ27="","",'Model inputs'!AJ27),IF(IF(IF(ISERROR('Model inputs'!O186>'Model inputs'!AJ26),'Model inputs'!O186>'Model inputs'!AJ26,IF(OR('Model inputs'!O186="",'Model inputs'!AJ26=""),"",'Model inputs'!O186>'Model inputs'!AJ26))="",FALSE,IF(ISERROR('Model inputs'!O186>'Model inputs'!AJ26),'Model inputs'!O186>'Model inputs'!AJ26,IF(OR('Model inputs'!O186="",'Model inputs'!AJ26=""),"",'Model inputs'!O186>'Model inputs'!AJ26))),'Model inputs'!N189*'Model inputs'!AJ23,0)) -> 50 | P9: =IF(IF(IF(ISERROR('Model inputs'!P186='Model inputs'!AJ26),'Model inputs'!P186='Model inputs'!AJ26,IF(OR('Model inputs'!P186="",'Model inputs'!AJ26=""),"",'Model inputs'!P186='Model inputs'!AJ26))="",FALSE,IF(ISERROR('Model inputs'!P186='Model inputs'!AJ26),'Model inputs'!P186='Model inputs'!AJ26,IF(OR('Model inputs'!P186="",'Model inputs'!AJ26=""),"",'Model inputs'!P186='Model inputs'!AJ26))),IF('Model inputs'!AJ27="","",'Model inputs'!AJ27),IF(IF(IF(ISERROR('Model inputs'!P186>'Model inputs'!AJ26),'Model inputs'!P186>'Model inputs'!AJ26,IF(OR('Model inputs'!P186="",'Model inputs'!AJ26=""),"",'Model inputs'!P186>'Model inputs'!AJ26))="",FALSE,IF(ISERROR('Model inputs'!P186>'Model inputs'!AJ26),'Model inputs'!P186>'Model inputs'!AJ26,IF(OR('Model inputs'!P186="",'Model inputs'!AJ26=""),"",'Model inputs'!P186>'Model inputs'!AJ26))),'Model inputs'!O189*'Model inputs'!AJ23,0)) -> 10 | Q9: =IF(IF(IF(ISERROR('Model inputs'!Q186='Model inputs'!AJ26),'Model inputs'!Q186='Model inputs'!AJ26,IF(OR('Model inputs'!Q186="",'Model inputs'!AJ26=""),"",'Model inputs'!Q186='Model inputs'!AJ26))="",FALSE,IF(ISERROR('Model inputs'!Q186='Model inputs'!AJ26),'Model inputs'!Q186='Model inputs'!AJ26,IF(OR('Model inputs'!Q186="",'Model inputs'!AJ26=""),"",'Model inputs'!Q186='Model inputs'!AJ26))),IF('Model inputs'!AJ27="","",'Model inputs'!AJ27),IF(IF(IF(ISERROR('Model inputs'!Q186>'Model inputs'!AJ26),'Model inputs'!Q186>'Model inputs'!AJ26,IF(OR('Model inputs'!Q186="",'Model inputs'!AJ26=""),"",'Model inputs'!Q186>'Model inputs'!AJ26))="",FALSE,IF(ISERROR('Model inputs'!Q186>'Model inputs'!AJ26),'Model inputs'!Q186>'Model inputs'!AJ26,IF(OR('Model inputs'!Q186="",'Model inputs'!AJ26=""),"",'Model inputs'!Q186>'Model inputs'!AJ26))),'Model inputs'!P189*'Model inputs'!AJ23,0)) -> 11.5 | R9: =IF(IF(IF(ISERROR('Model inputs'!R186='Model inputs'!AJ26),'Model inputs'!R186='Model inputs'!AJ26,IF(OR('Model inputs'!R186="",'Model inputs'!AJ26=""),"",'Model inputs'!R186='Model inputs'!AJ26))="",FALSE,IF(ISERROR('Model inputs'!R186='Model inputs'!AJ26),'Model inputs'!R186='Model inputs'!AJ26,IF(OR('Model inputs'!R186="",'Model inputs'!AJ26=""),"",'Model inputs'!R186='Model inputs'!AJ26))),IF('Model inputs'!AJ27="","",'Model inputs'!AJ27),IF(IF(IF(ISERROR('Model inputs'!R186>'Model inputs'!AJ26),'Model inputs'!R186>'Model inputs'!AJ26,IF(OR('Model inputs'!R186="",'Model inputs'!AJ26=""),"",'Model inputs'!R186>'Model inputs'!AJ26))="",FALSE,IF(ISERROR('Model inputs'!R186>'Model inputs'!AJ26),'Model inputs'!R186>'Model inputs'!AJ26,IF(OR('Model inputs'!R186="",'Model inputs'!AJ26=""),"",'Model inputs'!R186>'Model inputs'!AJ26))),'Model inputs'!Q189*'Model inputs'!AJ23,0)) -> 13.225 | S9: =IF(IF(IF(ISERROR('Model inputs'!S186='Model inputs'!AJ26),'Model inputs'!S186='Model inputs'!AJ26,IF(OR('Model inputs'!S186="",'Model inputs'!AJ26=""),"",'Model inputs'!S186='Model inputs'!AJ26))="",FALSE,IF(ISERROR('Model inputs'!S186='Model inputs'!AJ26),'Model inputs'!S186='Model inputs'!AJ26,IF(OR('Model inputs'!S186="",'Model inputs'!AJ26=""),"",'Model inputs'!S186='Model inputs'!AJ26))),IF('Model inputs'!AJ27="","",'Model inputs'!AJ27),IF(IF(IF(ISERROR('Model inputs'!S186>'Model inputs'!AJ26),'Model inputs'!S186>'Model inputs'!AJ26,IF(OR('Model inputs'!S186="",'Model inputs'!AJ26=""),"",'Model inputs'!S186>'Model inputs'!AJ26))="",FALSE,IF(ISERROR('Model inputs'!S186>'Model inputs'!AJ26),'Model inputs'!S186>'Model inputs'!AJ26,IF(OR('Model inputs'!S186="",'Model inputs'!AJ26=""),"",'Model inputs'!S186>'Model inputs'!AJ26))),'Model inputs'!R189*'Model inputs'!AJ23,0)) -> 15.20875 | T9: =IF(IF(IF(ISERROR('Model inputs'!T186='Model inputs'!AJ26),'Model inputs'!T186='Model inputs'!AJ26,IF(OR('Model inputs'!T186="",'Model inputs'!AJ26=""),"",'Model inputs'!T186='Model inputs'!AJ26))="",FALSE,IF(ISERROR('Model inputs'!T186='Model inputs'!AJ26),'Model inputs'!T186='Model inputs'!AJ26,IF(OR('Model inputs'!T186="",'Model inputs'!AJ26=""),"",'Model inputs'!T186='Model inputs'!AJ26))),IF('Model inputs'!AJ27="","",'Model inputs'!AJ27),IF(IF(IF(ISERROR('Model inputs'!T186>'Model inputs'!AJ26),'Model inputs'!T186>'Model inputs'!AJ26,IF(OR('Model inputs'!T186="",'Model inputs'!AJ26=""),"",'Model inputs'!T186>'Model inputs'!AJ26))="",FALSE,IF(ISERROR('Model inputs'!T186>'Model inputs'!AJ26),'Model inputs'!T186>'Model inputs'!AJ26,IF(OR('Model inputs'!T186="",'Model inputs'!AJ26=""),"",'Model inputs'!T186>'Model inputs'!AJ26))),'Model inputs'!S189*'Model inputs'!AJ23,0)) -> 17.490062 | U9: =IF(IF(IF(ISERROR('Model inputs'!U186='Model inputs'!AJ26),'Model inputs'!U186='Model inputs'!AJ26,IF(OR('Model inputs'!U186="",'Model inputs'!AJ26=""),"",'Model inputs'!U186='Model inputs'!AJ26))="",FALSE,IF(ISERROR('Model inputs'!U186='Model inputs'!AJ26),'Model inputs'!U186='Model inputs'!AJ26,IF(OR('Model inputs'!U186="",'Model inputs'!AJ26=""),"",'Model inputs'!U186='Model inputs'!AJ26))),IF('Model inputs'!AJ27="","",'Model inputs'!AJ27),IF(IF(IF(ISERROR('Model inputs'!U186>'Model inputs'!AJ26),'Model inputs'!U186>'Model inputs'!AJ26,IF(OR('Model inputs'!U186="",'Model inputs'!AJ26=""),"",'Model inputs'!U186>'Model inputs'!AJ26))="",FALSE,IF(ISERROR('Model inputs'!U186>'Model inputs'!AJ26),'Model inputs'!U186>'Model inputs'!AJ26,IF(OR('Model inputs'!U186="",'Model inputs'!AJ26=""),"",'Model inputs'!U186>'Model inputs'!AJ26))),'Model inputs'!T189*'Model inputs'!AJ23,0)) -> 20.113572 | V9: =IF(IF(IF(ISERROR('Model inputs'!V186='Model inputs'!AJ26),'Model inputs'!V186='Model inputs'!AJ26,IF(OR('Model inputs'!V186="",'Model inputs'!AJ26=""),"",'Model inputs'!V186='Model inputs'!AJ26))="",FALSE,IF(ISERROR('Model inputs'!V186='Model inputs'!AJ26),'Model inputs'!V186='Model inputs'!AJ26,IF(OR('Model inputs'!V186="",'Model inputs'!AJ26=""),"",'Model inputs'!V186='Model inputs'!AJ26))),IF('Model inputs'!AJ27="","",'Model inputs'!AJ27),IF(IF(IF(ISERROR('Model inputs'!V186>'Model inputs'!AJ26),'Model inputs'!V186>'Model inputs'!AJ26,IF(OR('Model inputs'!V186="",'Model inputs'!AJ26=""),"",'Model inputs'!V186>'Model inputs'!AJ26))="",FALSE,IF(ISERROR('Model inputs'!V186>'Model inputs'!AJ26),'Model inputs'!V186>'Model inputs'!AJ26,IF(OR('Model inputs'!V186="",'Model inputs'!AJ26=""),"",'Model inputs'!V186>'Model inputs'!AJ26))),'Model inputs'!U189*'Model inputs'!AJ23,0)) -> 23.130608 | W9: =IF(IF(IF(ISERROR('Model inputs'!W186='Model inputs'!AJ26),'Model inputs'!W186='Model inputs'!AJ26,IF(OR('Model inputs'!W186="",'Model inputs'!AJ26=""),"",'Model inputs'!W186='Model inputs'!AJ26))="",FALSE,IF(ISERROR('Model inputs'!W186='Model inputs'!AJ26),'Model inputs'!W186='Model inputs'!AJ26,IF(OR('Model inputs'!W186="",'Model inputs'!AJ26=""),"",'Model inputs'!W186='Model inputs'!AJ26))),IF('Model inputs'!AJ27="","",'Model inputs'!AJ27),IF(IF(IF(ISERROR('Model inputs'!W186>'Model inputs'!AJ26),'Model inputs'!W186>'Model inputs'!AJ26,IF(OR('Model inputs'!W186="",'Model inputs'!AJ26=""),"",'Model inputs'!W186>'Model inputs'!AJ26))="",FALSE,IF(ISERROR('Model inputs'!W186>'Model inputs'!AJ26),'Model inputs'!W186>'Model inputs'!AJ26,IF(OR('Model inputs'!W186="",'Model inputs'!AJ26=""),"",'Model inputs'!W186>'Model inputs'!AJ26))),'Model inputs'!V189*'Model inputs'!AJ23,0)) -> 26.600199 | X9: =IF(IF(IF(ISERROR('Model inputs'!X186='Model inputs'!AJ26),'Model inputs'!X186='Model inputs'!AJ26,IF(OR('Model inputs'!X186="",'Model inputs'!AJ26=""),"",'Model inputs'!X186='Model inputs'!AJ26))="",FALSE,IF(ISERROR('Model inputs'!X186='Model inputs'!AJ26),'Model inputs'!X186='Model inputs'!AJ26,IF(OR('Model inputs'!X186="",'Model inputs'!AJ26=""),"",'Model inputs'!X186='Model inputs'!AJ26))),IF('Model inputs'!AJ27="","",'Model inputs'!AJ27),IF(IF(IF(ISERROR('Model inputs'!X186>'Model inputs'!AJ26),'Model inputs'!X186>'Model inputs'!AJ26,IF(OR('Model inputs'!X186="",'Model inputs'!AJ26=""),"",'Model inputs'!X186>'Model inputs'!AJ26))="",FALSE,IF(ISERROR('Model inputs'!X186>'Model inputs'!AJ26),'Model inputs'!X186>'Model inputs'!AJ26,IF(OR('Model inputs'!X186="",'Model inputs'!AJ26=""),"",'Model inputs'!X186>'Model inputs'!AJ26))),'Model inputs'!W189*'Model inputs'!AJ23,0)) -> 30.590229 | Y9: =IF(IF(IF(ISERROR('Model inputs'!Y186='Model inputs'!AJ26),'Model inputs'!Y186='Model inputs'!AJ26,IF(OR('Model inputs'!Y186="",'Model inputs'!AJ26=""),"",'Model inputs'!Y186='Model inputs'!AJ26))="",FALSE,IF(ISERROR('Model inputs'!Y186='Model inputs'!AJ26),'Model inputs'!Y186='Model inputs'!AJ26,IF(OR('Model inputs'!Y186="",'Model inputs'!AJ26=""),"",'Model inputs'!Y186='Model inputs'!AJ26))),IF('Model inputs'!AJ27="","",'Model inputs'!AJ27),IF(IF(IF(ISERROR('Model inputs'!Y186>'Model inputs'!AJ26),'Model inputs'!Y186>'Model inputs'!AJ26,IF(OR('Model inputs'!Y186="",'Model inputs'!AJ26=""),"",'Model inputs'!Y186>'Model inputs'!AJ26))="",FALSE,IF(ISERROR('Model inputs'!Y186>'Model inputs'!AJ26),'Model inputs'!Y186>'Model inputs'!AJ26,IF(OR('Model inputs'!Y186="",'Model inputs'!AJ26=""),"",'Model inputs'!Y186>'Model inputs'!AJ26))),'Model inputs'!X189*'Model inputs'!AJ23,0)) -> 35.178763 | Z9: =IF(IF(IF(ISERROR('Model inputs'!Z186='Model inputs'!AJ26),'Model inputs'!Z186='Model inputs'!AJ26,IF(OR('Model inputs'!Z186="",'Model inputs'!AJ26=""),"",'Model inputs'!Z186='Model inputs'!AJ26))="",FALSE,IF(ISERROR('Model inputs'!Z186='Model inputs'!AJ26),'Model inputs'!Z186='Model inputs'!AJ26,IF(OR('Model inputs'!Z186="",'Model inputs'!AJ26=""),"",'Model inputs'!Z186='Model inputs'!AJ26))),IF('Model inputs'!AJ27="","",'Model inputs'!AJ27),IF(IF(IF(ISERROR('Model inputs'!Z186>'Model inputs'!AJ26),'Model inputs'!Z186>'Model inputs'!AJ26,IF(OR('Model inputs'!Z186="",'Model inputs'!AJ26=""),"",'Model inputs'!Z186>'Model inputs'!AJ26))="",FALSE,IF(ISERROR('Model inputs'!Z186>'Model inputs'!AJ26),'Model inputs'!Z186>'Model inputs'!AJ26,IF(OR('Model inputs'!Z186="",'Model inputs'!AJ26=""),"",'Model inputs'!Z186>'Model inputs'!AJ26))),'Model inputs'!Y189*'Model inputs'!AJ23,0)) -> 40.455577 | AA9: =IF(IF(IF(ISERROR('Model inputs'!AA186='Model inputs'!AJ26),'Model inputs'!AA186='Model inputs'!AJ26,IF(OR('Model inputs'!AA186="",'Model inputs'!AJ26=""),"",'Model inputs'!AA186='Model inputs'!AJ26))="",FALSE,IF(ISERROR('Model inputs'!AA186='Model inputs'!AJ26),'Model inputs'!AA186='Model inputs'!AJ26,IF(OR('Model inputs'!AA186="",'Model inputs'!AJ26=""),"",'Model inputs'!AA186='Model inputs'!AJ26))),IF('Model inputs'!AJ27="","",'Model inputs'!AJ27),IF(IF(IF(ISERROR('Model inputs'!AA186>'Model inputs'!AJ26),'Model inputs'!AA186>'Model inputs'!AJ26,IF(OR('Model inputs'!AA186="",'Model inputs'!AJ26=""),"",'Model inputs'!AA186>'Model inputs'!AJ26))="",FALSE,IF(ISERROR('Model inputs'!AA186>'Model inputs'!AJ26),'Model inputs'!AA186>'Model inputs'!AJ26,IF(OR('Model inputs'!AA186="",'Model inputs'!AJ26=""),"",'Model inputs'!AA186>'Model inputs'!AJ26))),'Model inputs'!Z189*'Model inputs'!AJ23,0)) -> 46.523914 | AB9: =IF(IF(IF(ISERROR('Model inputs'!AB186='Model inputs'!AJ26),'Model inputs'!AB186='Model inputs'!AJ26,IF(OR('Model inputs'!AB186="",'Model inputs'!AJ26=""),"",'Model inputs'!AB186='Model inputs'!AJ26))="",FALSE,IF(ISERROR('Model inputs'!AB186='Model inputs'!AJ26),'Model inputs'!AB186='Model inputs'!AJ26,IF(OR('Model inputs'!AB186="",'Model inputs'!AJ26=""),"",'Model inputs'!AB186='Model inputs'!AJ26))),IF('Model inputs'!AJ27="","",'Model inputs'!AJ27),IF(IF(IF(ISERROR('Model inputs'!AB186>'Model inputs'!AJ26),'Model inputs'!AB186>'Model inputs'!AJ26,IF(OR('Model inputs'!AB186="",'Model inputs'!AJ26=""),"",'Model inputs'!AB186>'Model inputs'!AJ26))="",FALSE,IF(ISERROR('Model inputs'!AB186>'Model inputs'!AJ26),'Model inputs'!AB186>'Model inputs'!AJ26,IF(OR('Model inputs'!AB186="",'Model inputs'!AJ26=""),"",'Model inputs'!AB186>'Model inputs'!AJ26))),'Model inputs'!AA189*'Model inputs'!AJ23,0)) -> 53.502501 | AC9: =IF(IF(IF(ISERROR('Model inputs'!AC186='Model inputs'!AJ26),'Model inputs'!AC186='Model inputs'!AJ26,IF(OR('Model inputs'!AC186="",'Model inputs'!AJ26=""),"",'Model inputs'!AC186='Model inputs'!AJ26))="",FALSE,IF(ISERROR('Model inputs'!AC186='Model inputs'!AJ26),'Model inputs'!AC186='Model inputs'!AJ26,IF(OR('Model inputs'!AC186="",'Model inputs'!AJ26=""),"",'Model inputs'!AC186='Model inputs'!AJ26))),IF('Model inputs'!AJ27="","",'Model inputs'!AJ27),IF(IF(IF(ISERROR('Model inputs'!AC186>'Model inputs'!AJ26),'Model inputs'!AC186>'Model inputs'!AJ26,IF(OR('Model inputs'!AC186="",'Model inputs'!AJ26=""),"",'Model inputs'!AC186>'Model inputs'!AJ26))="",FALSE,IF(ISERROR('Model inputs'!AC186>'Model inputs'!AJ26),'Model inputs'!AC186>'Model inputs'!AJ26,IF(OR('Model inputs'!AC186="",'Model inputs'!AJ26=""),"",'Model inputs'!AC186>'Model inputs'!AJ26))),'Model inputs'!AB189*'Model inputs'!AJ23,0)) -> 61.527876 | AD9: =IF(IF(IF(ISERROR('Model inputs'!AD186='Model inputs'!AJ26),'Model inputs'!AD186='Model inputs'!AJ26,IF(OR('Model inputs'!AD186="",'Model inputs'!AJ26=""),"",'Model inputs'!AD186='Model inputs'!AJ26))="",FALSE,IF(ISERROR('Model inputs'!AD186='Model inputs'!AJ26),'Model inputs'!AD186='Model inputs'!AJ26,IF(OR('Model inputs'!AD186="",'Model inputs'!AJ26=""),"",'Model inputs'!AD186='Model inputs'!AJ26))),IF('Model inputs'!AJ27="","",'Model inputs'!AJ27),IF(IF(IF(ISERROR('Model inputs'!AD186>'Model inputs'!AJ26),'Model inputs'!AD186>'Model inputs'!AJ26,IF(OR('Model inputs'!AD186="",'Model inputs'!AJ26=""),"",'Model inputs'!AD186>'Model inputs'!AJ26))="",FALSE,IF(ISERROR('Model inputs'!AD186>'Model inputs'!AJ26),'Model inputs'!AD186>'Model inputs'!AJ26,IF(OR('Model inputs'!AD186="",'Model inputs'!AJ26=""),"",'Model inputs'!AD186>'Model inputs'!AJ26))),'Model inputs'!AC189*'Model inputs'!AJ23,0)) -> 70.757058 | AE9: =IF(IF(IF(ISERROR('Model inputs'!AE186='Model inputs'!AJ26),'Model inputs'!AE186='Model inputs'!AJ26,IF(OR('Model inputs'!AE186="",'Model inputs'!AJ26=""),"",'Model inputs'!AE186='Model inputs'!AJ26))="",FALSE,IF(ISERROR('Model inputs'!AE186='Model inputs'!AJ26),'Model inputs'!AE186='Model inputs'!AJ26,IF(OR('Model inputs'!AE186="",'Model inputs'!AJ26=""),"",'Model inputs'!AE186='Model inputs'!AJ26))),IF('Model inputs'!AJ27="","",'Model inputs'!AJ27),IF(IF(IF(ISERROR('Model inputs'!AE186>'Model inputs'!AJ26),'Model inputs'!AE186>'Model inputs'!AJ26,IF(OR('Model inputs'!AE186="",'Model inputs'!AJ26=""),"",'Model inputs'!AE186>'Model inputs'!AJ26))="",FALSE,IF(ISERROR('Model inputs'!AE186>'Model inputs'!AJ26),'Model inputs'!AE186>'Model inputs'!AJ26,IF(OR('Model inputs'!AE186="",'Model inputs'!AJ26=""),"",'Model inputs'!AE186>'Model inputs'!AJ26))),'Model inputs'!AD189*'Model inputs'!AJ23,0)) -> 81.370616 | AF9: =IF(IF(IF(ISERROR('Model inputs'!AF186='Model inputs'!AJ26),'Model inputs'!AF186='Model inputs'!AJ26,IF(OR('Model inputs'!AF186="",'Model inputs'!AJ26=""),"",'Model inputs'!AF186='Model inputs'!AJ26))="",FALSE,IF(ISERROR('Model inputs'!AF186='Model inputs'!AJ26),'Model inputs'!AF186='Model inputs'!AJ26,IF(OR('Model inputs'!AF186="",'Model inputs'!AJ26=""),"",'Model inputs'!AF186='Model inputs'!AJ26))),IF('Model inputs'!AJ27="","",'Model inputs'!AJ27),IF(IF(IF(ISERROR('Model inputs'!AF186>'Model inputs'!AJ26),'Model inputs'!AF186>'Model inputs'!AJ26,IF(OR('Model inputs'!AF186="",'Model inputs'!AJ26=""),"",'Model inputs'!AF186>'Model inputs'!AJ26))="",FALSE,IF(ISERROR('Model inputs'!AF186>'Model inputs'!AJ26),'Model inputs'!AF186>'Model inputs'!AJ26,IF(OR('Model inputs'!AF186="",'Model inputs'!AJ26=""),"",'Model inputs'!AF186>'Model inputs'!AJ26))),'Model inputs'!AE189*'Model inputs'!AJ23,0)) -> 93.576209 | AG9: =IF(IF(IF(ISERROR('Model inputs'!AG186='Model inputs'!AJ26),'Model inputs'!AG186='Model inputs'!AJ26,IF(OR('Model inputs'!AG186="",'Model inputs'!AJ26=""),"",'Model inputs'!AG186='Model inputs'!AJ26))="",FALSE,IF(ISERROR('Model inputs'!AG186='Model inputs'!AJ26),'Model inputs'!AG186='Model inputs'!AJ26,IF(OR('Model inputs'!AG186="",'Model inputs'!AJ26=""),"",'Model inputs'!AG186='Model inputs'!AJ26))),IF('Model inputs'!AJ27="","",'Model inputs'!AJ27),IF(IF(IF(ISERROR('Model inputs'!AG186>'Model inputs'!AJ26),'Model inputs'!AG186>'Model inputs'!AJ26,IF(OR('Model inputs'!AG186="",'Model inputs'!AJ26=""),"",'Model inputs'!AG186>'Model inputs'!AJ26))="",FALSE,IF(ISERROR('Model inputs'!AG186>'Model inputs'!AJ26),'Model inputs'!AG186>'Model inputs'!AJ26,IF(OR('Model inputs'!AG186="",'Model inputs'!AJ26=""),"",'Model inputs'!AG186>'Model inputs'!AJ26))),'Model inputs'!AF189*'Model inputs'!AJ23,0)) -> 107.61264 | AH9: =IF(IF(IF(ISERROR('Model inputs'!AH186='Model inputs'!AJ26),'Model inputs'!AH186='Model inputs'!AJ26,IF(OR('Model inputs'!AH186="",'Model inputs'!AJ26=""),"",'Model inputs'!AH186='Model inputs'!AJ26))="",FALSE,IF(ISERROR('Model inputs'!AH186='Model inputs'!AJ26),'Model inputs'!AH186='Model inputs'!AJ26,IF(OR('Model inputs'!AH186="",'Model inputs'!AJ26=""),"",'Model inputs'!AH186='Model inputs'!AJ26))),IF('Model inputs'!AJ27="","",'Model inputs'!AJ27),IF(IF(IF(ISERROR('Model inputs'!AH186>'Model inputs'!AJ26),'Model inputs'!AH186>'Model inputs'!AJ26,IF(OR('Model inputs'!AH186="",'Model inputs'!AJ26=""),"",'Model inputs'!AH186>'Model inputs'!AJ26))="",FALSE,IF(ISERROR('Model inputs'!AH186>'Model inputs'!AJ26),'Model inputs'!AH186>'Model inputs'!AJ26,IF(OR('Model inputs'!AH186="",'Model inputs'!AJ26=""),"",'Model inputs'!AH186>'Model inputs'!AJ26))),'Model inputs'!AG189*'Model inputs'!AJ23,0)) -> 123.75454 | AI9: =IF(IF(IF(ISERROR('Model inputs'!AI186='Model inputs'!AJ26),'Model inputs'!AI186='Model inputs'!AJ26,IF(OR('Model inputs'!AI186="",'Model inputs'!AJ26=""),"",'Model inputs'!AI186='Model inputs'!AJ26))="",FALSE,IF(ISERROR('Model inputs'!AI186='Model inputs'!AJ26),'Model inputs'!AI186='Model inputs'!AJ26,IF(OR('Model inputs'!AI186="",'Model inputs'!AJ26=""),"",'Model inputs'!AI186='Model inputs'!AJ26))),IF('Model inputs'!AJ27="","",'Model inputs'!AJ27),IF(IF(IF(ISERROR('Model inputs'!AI186>'Model inputs'!AJ26),'Model inputs'!AI186>'Model inputs'!AJ26,IF(OR('Model inputs'!AI186="",'Model inputs'!AJ26=""),"",'Model inputs'!AI186>'Model inputs'!AJ26))="",FALSE,IF(ISERROR('Model inputs'!AI186>'Model inputs'!AJ26),'Model inputs'!AI186>'Model inputs'!AJ26,IF(OR('Model inputs'!AI186="",'Model inputs'!AJ26=""),"",'Model inputs'!AI186>'Model inputs'!AJ26))),'Model inputs'!AH189*'Model inputs'!AJ23,0)) -> 142.31772
