Workbook

Sheet Haq — Monthly P&L and cash
A1: Haq — Monthly P&L and cash
A2: Haq — Monthly plan · Main Scenario
A4: Variable / dimension | B4: 2026-11 | C4: 2026-12 | D4: 2027-01 | E4: 2027-02 | F4: 2027-03 | G4: 2027-04 | H4: 2027-05 | I4: 2027-06 | J4: 2027-07 | K4: 2027-08 | L4: 2027-09 | M4: 2027-10 | N4: 2027-11 | O4: 2027-12 | P4: 2028-01 | Q4: 2028-02 | R4: 2028-03 | S4: 2028-04 | T4: 2028-05 | U4: 2028-06 | V4: 2028-07 | W4: 2028-08 | X4: 2028-09 | Y4: 2028-10
A5: Haq month | B5: =(YEAR(DATE(2026,11,1))-2026)*12+MONTH(DATE(2026,11,1))-10 -> 1 | C5: =(YEAR(DATE(2026,12,1))-2026)*12+MONTH(DATE(2026,12,1))-10 -> 2 | D5: =(YEAR(DATE(2027,1,1))-2026)*12+MONTH(DATE(2027,1,1))-10 -> 3 | E5: =(YEAR(DATE(2027,2,1))-2026)*12+MONTH(DATE(2027,2,1))-10 -> 4 | F5: =(YEAR(DATE(2027,3,1))-2026)*12+MONTH(DATE(2027,3,1))-10 -> 5 | G5: =(YEAR(DATE(2027,4,1))-2026)*12+MONTH(DATE(2027,4,1))-10 -> 6 | H5: =(YEAR(DATE(2027,5,1))-2026)*12+MONTH(DATE(2027,5,1))-10 -> 7 | I5: =(YEAR(DATE(2027,6,1))-2026)*12+MONTH(DATE(2027,6,1))-10 -> 8 | J5: =(YEAR(DATE(2027,7,1))-2026)*12+MONTH(DATE(2027,7,1))-10 -> 9 | K5: =(YEAR(DATE(2027,8,1))-2026)*12+MONTH(DATE(2027,8,1))-10 -> 10 | L5: =(YEAR(DATE(2027,9,1))-2026)*12+MONTH(DATE(2027,9,1))-10 -> 11 | M5: =(YEAR(DATE(2027,10,1))-2026)*12+MONTH(DATE(2027,10,1))-10 -> 12 | N5: =(YEAR(DATE(2027,11,1))-2026)*12+MONTH(DATE(2027,11,1))-10 -> 13 | O5: =(YEAR(DATE(2027,12,1))-2026)*12+MONTH(DATE(2027,12,1))-10 -> 14 | P5: =(YEAR(DATE(2028,1,1))-2026)*12+MONTH(DATE(2028,1,1))-10 -> 15 | Q5: =(YEAR(DATE(2028,2,1))-2026)*12+MONTH(DATE(2028,2,1))-10 -> 16 | R5: =(YEAR(DATE(2028,3,1))-2026)*12+MONTH(DATE(2028,3,1))-10 -> 17 | S5: =(YEAR(DATE(2028,4,1))-2026)*12+MONTH(DATE(2028,4,1))-10 -> 18 | T5: =(YEAR(DATE(2028,5,1))-2026)*12+MONTH(DATE(2028,5,1))-10 -> 19 | U5: =(YEAR(DATE(2028,6,1))-2026)*12+MONTH(DATE(2028,6,1))-10 -> 20 | V5: =(YEAR(DATE(2028,7,1))-2026)*12+MONTH(DATE(2028,7,1))-10 -> 21 | W5: =(YEAR(DATE(2028,8,1))-2026)*12+MONTH(DATE(2028,8,1))-10 -> 22 | X5: =(YEAR(DATE(2028,9,1))-2026)*12+MONTH(DATE(2028,9,1))-10 -> 23 | Y5: =(YEAR(DATE(2028,10,1))-2026)*12+MONTH(DATE(2028,10,1))-10 -> 24
A6: Haq check cost | B6: =IF(IF(IF(ISERROR('Haq — Monthly P&L and cash'!B5<'Model inputs'!AJ54),'Haq — Monthly P&L and cash'!B5<'Model inputs'!AJ54,IF(OR('Haq — Monthly P&L and cash'!B5="",'Model inputs'!AJ54=""),"",'Haq — Monthly P&L and cash'!B5<'Model inputs'!AJ54))="",FALSE,IF(ISERROR('Haq — Monthly P&L and cash'!B5<'Model inputs'!AJ54),'Haq — Monthly P&L and cash'!B5<'Model inputs'!AJ54,IF(OR('Haq — Monthly P&L and cash'!B5="",'Model inputs'!AJ54=""),"",'Haq — Monthly P&L and cash'!B5<'Model inputs'!AJ54))),IF('Model inputs'!AJ87="","",'Model inputs'!AJ87),IF(IF(IF(ISERROR('Haq — Monthly P&L and cash'!B5<'Model inputs'!AJ84),'Haq — Monthly P&L and cash'!B5<'Model inputs'!AJ84,IF(OR('Haq — Monthly P&L and cash'!B5="",'Model inputs'!AJ84=""),"",'Haq — Monthly P&L and cash'!B5<'Model inputs'!AJ84))="",FALSE,IF(ISERROR('Haq — Monthly P&L and cash'!B5<'Model inputs'!AJ84),'Haq — Monthly P&L and cash'!B5<'Model inputs'!AJ84,IF(OR('Haq — Monthly P&L and cash'!B5="",'Model inputs'!AJ84=""),"",'Haq — Monthly P&L and cash'!B5<'Model inputs'!AJ84))),IF('Model inputs'!AJ55="","",'Model inputs'!AJ55),IF('Model inputs'!AJ85="","",'Model inputs'!AJ85))) -> 20 | C6: =IF(IF(IF(ISERROR('Haq — Monthly P&L and cash'!C5<'Model inputs'!AJ54),'Haq — Monthly P&L and cash'!C5<'Model inputs'!AJ54,IF(OR('Haq — Monthly P&L and cash'!C5="",'Model inputs'!AJ54=""),"",'Haq — Monthly P&L and cash'!C5<'Model inputs'!AJ54))="",FALSE,IF(ISERROR('Haq — Monthly P&L and cash'!C5<'Model inputs'!AJ54),'Haq — Monthly P&L and cash'!C5<'Model inputs'!AJ54,IF(OR('Haq — Monthly P&L and cash'!C5="",'Model inputs'!AJ54=""),"",'Haq — Monthly P&L and cash'!C5<'Model inputs'!AJ54))),IF('Model inputs'!AJ87="","",'Model inputs'!AJ87),IF(IF(IF(ISERROR('Haq — Monthly P&L and cash'!C5<'Model inputs'!AJ84),'Haq — Monthly P&L and cash'!C5<'Model inputs'!AJ84,IF(OR('Haq — Monthly P&L and cash'!C5="",'Model inputs'!AJ84=""),"",'Haq — Monthly P&L and cash'!C5<'Model inputs'!AJ84))="",FALSE,IF(ISERROR('Haq — Monthly P&L and cash'!C5<'Model inputs'!AJ84),'Haq — Monthly P&L and cash'!C5<'Model inputs'!AJ84,IF(OR('Haq — Monthly P&L and cash'!C5="",'Model inputs'!AJ84=""),"",'Haq — Monthly P&L and cash'!C5<'Model inputs'!AJ84))),IF('Model inputs'!AJ55="","",'Model inputs'!AJ55),IF('Model inputs'!AJ85="","",'Model inputs'!AJ85))) -> 20 | D6: =IF(IF(IF(ISERROR('Haq — Monthly P&L and cash'!D5<'Model inputs'!AJ54),'Haq — Monthly P&L and cash'!D5<'Model inputs'!AJ54,IF(OR('Haq — Monthly P&L and cash'!D5="",'Model inputs'!AJ54=""),"",'Haq — Monthly P&L and cash'!D5<'Model inputs'!AJ54))="",FALSE,IF(ISERROR('Haq — Monthly P&L and cash'!D5<'Model inputs'!AJ54),'Haq — Monthly P&L and cash'!D5<'Model inputs'!AJ54,IF(OR('Haq — Monthly P&L and cash'!D5="",'Model inputs'!AJ54=""),"",'Haq — Monthly P&L and cash'!D5<'Model inputs'!AJ54))),IF('Model inputs'!AJ87="","",'Model inputs'!AJ87),IF(IF(IF(ISERROR('Haq — Monthly P&L and cash'!D5<'Model inputs'!AJ84),'Haq — Monthly P&L and cash'!D5<'Model inputs'!AJ84,IF(OR('Haq — Monthly P&L and cash'!D5="",'Model inputs'!AJ84=""),"",'Haq — Monthly P&L and cash'!D5<'Model inputs'!AJ84))="",FALSE,IF(ISERROR('Haq — Monthly P&L and cash'!D5<'Model inputs'!AJ84),'Haq — Monthly P&L and cash'!D5<'Model inputs'!AJ84,IF(OR('Haq — Monthly P&L and cash'!D5="",'Model inputs'!AJ84=""),"",'Haq — Monthly P&L and cash'!D5<'Model inputs'!AJ84))),IF('Model inputs'!AJ55="","",'Model inputs'!AJ55),IF('Model inputs'!AJ85="","",'Model inputs'!AJ85))) -> 20 | E6: =IF(IF(IF(ISERROR('Haq — Monthly P&L and cash'!E5<'Model inputs'!AJ54),'Haq — Monthly P&L and cash'!E5<'Model inputs'!AJ54,IF(OR('Haq — Monthly P&L and cash'!E5="",'Model inputs'!AJ54=""),"",'Haq — Monthly P&L and cash'!E5<'Model inputs'!AJ54))="",FALSE,IF(ISERROR('Haq — Monthly P&L and cash'!E5<'Model inputs'!AJ54),'Haq — Monthly P&L and cash'!E5<'Model inputs'!AJ54,IF(OR('Haq — Monthly P&L and cash'!E5="",'Model inputs'!AJ54=""),"",'Haq — Monthly P&L and cash'!E5<'Model inputs'!AJ54))),IF('Model inputs'!AJ87="","",'Model inputs'!AJ87),IF(IF(IF(ISERROR('Haq — Monthly P&L and cash'!E5<'Model inputs'!AJ84),'Haq — Monthly P&L and cash'!E5<'Model inputs'!AJ84,IF(OR('Haq — Monthly P&L and cash'!E5="",'Model inputs'!AJ84=""),"",'Haq — Monthly P&L and cash'!E5<'Model inputs'!AJ84))="",FALSE,IF(ISERROR('Haq — Monthly P&L and cash'!E5<'Model inputs'!AJ84),'Haq — Monthly P&L and cash'!E5<'Model inputs'!AJ84,IF(OR('Haq — Monthly P&L and cash'!E5="",'Model inputs'!AJ84=""),"",'Haq — Monthly P&L and cash'!E5<'Model inputs'!AJ84))),IF('Model inputs'!AJ55="","",'Model inputs'!AJ55),IF('Model inputs'!AJ85="","",'Model inputs'!AJ85))) -> 10 | F6: =IF(IF(IF(ISERROR('Haq — Monthly P&L and cash'!F5<'Model inputs'!AJ54),'Haq — Monthly P&L and cash'!F5<'Model inputs'!AJ54,IF(OR('Haq — Monthly P&L and cash'!F5="",'Model inputs'!AJ54=""),"",'Haq — Monthly P&L and cash'!F5<'Model inputs'!AJ54))="",FALSE,IF(ISERROR('Haq — Monthly P&L and cash'!F5<'Model inputs'!AJ54),'Haq — Monthly P&L and cash'!F5<'Model inputs'!AJ54,IF(OR('Haq — Monthly P&L and cash'!F5="",'Model inputs'!AJ54=""),"",'Haq — Monthly P&L and cash'!F5<'Model inputs'!AJ54))),IF('Model inputs'!AJ87="","",'Model inputs'!AJ87),IF(IF(IF(ISERROR('Haq — Monthly P&L and cash'!F5<'Model inputs'!AJ84),'Haq — Monthly P&L and cash'!F5<'Model inputs'!AJ84,IF(OR('Haq — Monthly P&L and cash'!F5="",'Model inputs'!AJ84=""),"",'Haq — Monthly P&L and cash'!F5<'Model inputs'!AJ84))="",FALSE,IF(ISERROR('Haq — Monthly P&L and cash'!F5<'Model inputs'!AJ84),'Haq — Monthly P&L and cash'!F5<'Model inputs'!AJ84,IF(OR('Haq — Monthly P&L and cash'!F5="",'Model inputs'!AJ84=""),"",'Haq — Monthly P&L and cash'!F5<'Model inputs'!AJ84))),IF('Model inputs'!AJ55="","",'Model inputs'!AJ55),IF('Model inputs'!AJ85="","",'Model inputs'!AJ85))) -> 10 | G6: =IF(IF(IF(ISERROR('Haq — Monthly P&L and cash'!G5<'Model inputs'!AJ54),'Haq — Monthly P&L and cash'!G5<'Model inputs'!AJ54,IF(OR('Haq — Monthly P&L and cash'!G5="",'Model inputs'!AJ54=""),"",'Haq — Monthly P&L and cash'!G5<'Model inputs'!AJ54))="",FALSE,IF(ISERROR('Haq — Monthly P&L and cash'!G5<'Model inputs'!AJ54),'Haq — Monthly P&L and cash'!G5<'Model inputs'!AJ54,IF(OR('Haq — Monthly P&L and cash'!G5="",'Model inputs'!AJ54=""),"",'Haq — Monthly P&L and cash'!G5<'Model inputs'!AJ54))),IF('Model inputs'!AJ87="","",'Model inputs'!AJ87),IF(IF(IF(ISERROR('Haq — Monthly P&L and cash'!G5<'Model inputs'!AJ84),'Haq — Monthly P&L and cash'!G5<'Model inputs'!AJ84,IF(OR('Haq — Monthly P&L and cash'!G5="",'Model inputs'!AJ84=""),"",'Haq — Monthly P&L and cash'!G5<'Model inputs'!AJ84))="",FALSE,IF(ISERROR('Haq — Monthly P&L and cash'!G5<'Model inputs'!AJ84),'Haq — Monthly P&L and cash'!G5<'Model inputs'!AJ84,IF(OR('Haq — Monthly P&L and cash'!G5="",'Model inputs'!AJ84=""),"",'Haq — Monthly P&L and cash'!G5<'Model inputs'!AJ84))),IF('Model inputs'!AJ55="","",'Model inputs'!AJ55),IF('Model inputs'!AJ85="","",'Model inputs'!AJ85))) -> 10 | H6: =IF(IF(IF(ISERROR('Haq — Monthly P&L and cash'!H5<'Model inputs'!AJ54),'Haq — Monthly P&L and cash'!H5<'Model inputs'!AJ54,IF(OR('Haq — Monthly P&L and cash'!H5="",'Model inputs'!AJ54=""),"",'Haq — Monthly P&L and cash'!H5<'Model inputs'!AJ54))="",FALSE,IF(ISERROR('Haq — Monthly P&L and cash'!H5<'Model inputs'!AJ54),'Haq — Monthly P&L and cash'!H5<'Model inputs'!AJ54,IF(OR('Haq — Monthly P&L and cash'!H5="",'Model inputs'!AJ54=""),"",'Haq — Monthly P&L and cash'!H5<'Model inputs'!AJ54))),IF('Model inputs'!AJ87="","",'Model inputs'!AJ87),IF(IF(IF(ISERROR('Haq — Monthly P&L and cash'!H5<'Model inputs'!AJ84),'Haq — Monthly P&L and cash'!H5<'Model inputs'!AJ84,IF(OR('Haq — Monthly P&L and cash'!H5="",'Model inputs'!AJ84=""),"",'Haq — Monthly P&L and cash'!H5<'Model inputs'!AJ84))="",FALSE,IF(ISERROR('Haq — Monthly P&L and cash'!H5<'Model inputs'!AJ84),'Haq — Monthly P&L and cash'!H5<'Model inputs'!AJ84,IF(OR('Haq — Monthly P&L and cash'!H5="",'Model inputs'!AJ84=""),"",'Haq — Monthly P&L and cash'!H5<'Model inputs'!AJ84))),IF('Model inputs'!AJ55="","",'Model inputs'!AJ55),IF('Model inputs'!AJ85="","",'Model inputs'!AJ85))) -> 10 | I6: =IF(IF(IF(ISERROR('Haq — Monthly P&L and cash'!I5<'Model inputs'!AJ54),'Haq — Monthly P&L and cash'!I5<'Model inputs'!AJ54,IF(OR('Haq — Monthly P&L and cash'!I5="",'Model inputs'!AJ54=""),"",'Haq — Monthly P&L and cash'!I5<'Model inputs'!AJ54))="",FALSE,IF(ISERROR('Haq — Monthly P&L and cash'!I5<'Model inputs'!AJ54),'Haq — Monthly P&L and cash'!I5<'Model inputs'!AJ54,IF(OR('Haq — Monthly P&L and cash'!I5="",'Model inputs'!AJ54=""),"",'Haq — Monthly P&L and cash'!I5<'Model inputs'!AJ54))),IF('Model inputs'!AJ87="","",'Model inputs'!AJ87),IF(IF(IF(ISERROR('Haq — Monthly P&L and cash'!I5<'Model inputs'!AJ84),'Haq — Monthly P&L and cash'!I5<'Model inputs'!AJ84,IF(OR('Haq — Monthly P&L and cash'!I5="",'Model inputs'!AJ84=""),"",'Haq — Monthly P&L and cash'!I5<'Model inputs'!AJ84))="",FALSE,IF(ISERROR('Haq — Monthly P&L and cash'!I5<'Model inputs'!AJ84),'Haq — Monthly P&L and cash'!I5<'Model inputs'!AJ84,IF(OR('Haq — Monthly P&L and cash'!I5="",'Model inputs'!AJ84=""),"",'Haq — Monthly P&L and cash'!I5<'Model inputs'!AJ84))),IF('Model inputs'!AJ55="","",'Model inputs'!AJ55),IF('Model inputs'!AJ85="","",'Model inputs'!AJ85))) -> 10 | J6: =IF(IF(IF(ISERROR('Haq — Monthly P&L and cash'!J5<'Model inputs'!AJ54),'Haq — Monthly P&L and cash'!J5<'Model inputs'!AJ54,IF(OR('Haq — Monthly P&L and cash'!J5="",'Model inputs'!AJ54=""),"",'Haq — Monthly P&L and cash'!J5<'Model inputs'!AJ54))="",FALSE,IF(ISERROR('Haq — Monthly P&L and cash'!J5<'Model inputs'!AJ54),'Haq — Monthly P&L and cash'!J5<'Model inputs'!AJ54,IF(OR('Haq — Monthly P&L and cash'!J5="",'Model inputs'!AJ54=""),"",'Haq — Monthly P&L and cash'!J5<'Model inputs'!AJ54))),IF('Model inputs'!AJ87="","",'Model inputs'!AJ87),IF(IF(IF(ISERROR('Haq — Monthly P&L and cash'!J5<'Model inputs'!AJ84),'Haq — Monthly P&L and cash'!J5<'Model inputs'!AJ84,IF(OR('Haq — Monthly P&L and cash'!J5="",'Model inputs'!AJ84=""),"",'Haq — Monthly P&L and cash'!J5<'Model inputs'!AJ84))="",FALSE,IF(ISERROR('Haq — Monthly P&L and cash'!J5<'Model inputs'!AJ84),'Haq — Monthly P&L and cash'!J5<'Model inputs'!AJ84,IF(OR('Haq — Monthly P&L and cash'!J5="",'Model inputs'!AJ84=""),"",'Haq — Monthly P&L and cash'!J5<'Model inputs'!AJ84))),IF('Model inputs'!AJ55="","",'Model inputs'!AJ55),IF('Model inputs'!AJ85="","",'Model inputs'!AJ85))) -> 10 | K6: =IF(IF(IF(ISERROR('Haq — Monthly P&L and cash'!K5<'Model inputs'!AJ54),'Haq — Monthly P&L and cash'!K5<'Model inputs'!AJ54,IF(OR('Haq — Monthly P&L and cash'!K5="",'Model inputs'!AJ54=""),"",'Haq — Monthly P&L and cash'!K5<'Model inputs'!AJ54))="",FALSE,IF(ISERROR('Haq — Monthly P&L and cash'!K5<'Model inputs'!AJ54),'Haq — Monthly P&L and cash'!K5<'Model inputs'!AJ54,IF(OR('Haq — Monthly P&L and cash'!K5="",'Model inputs'!AJ54=""),"",'Haq — Monthly P&L and cash'!K5<'Model inputs'!AJ54))),IF('Model inputs'!AJ87="","",'Model inputs'!AJ87),IF(IF(IF(ISERROR('Haq — Monthly P&L and cash'!K5<'Model inputs'!AJ84),'Haq — Monthly P&L and cash'!K5<'Model inputs'!AJ84,IF(OR('Haq — Monthly P&L and cash'!K5="",'Model inputs'!AJ84=""),"",'Haq — Monthly P&L and cash'!K5<'Model inputs'!AJ84))="",FALSE,IF(ISERROR('Haq — Monthly P&L and cash'!K5<'Model inputs'!AJ84),'Haq — Monthly P&L and cash'!K5<'Model inputs'!AJ84,IF(OR('Haq — Monthly P&L and cash'!K5="",'Model inputs'!AJ84=""),"",'Haq — Monthly P&L and cash'!K5<'Model inputs'!AJ84))),IF('Model inputs'!AJ55="","",'Model inputs'!AJ55),IF('Model inputs'!AJ85="","",'Model inputs'!AJ85))) -> 4 | L6: =IF(IF(IF(ISERROR('Haq — Monthly P&L and cash'!L5<'Model inputs'!AJ54),'Haq — Monthly P&L and cash'!L5<'Model inputs'!AJ54,IF(OR('Haq — Monthly P&L and cash'!L5="",'Model inputs'!AJ54=""),"",'Haq — Monthly P&L and cash'!L5<'Model inputs'!AJ54))="",FALSE,IF(ISERROR('Haq — Monthly P&L and cash'!L5<'Model inputs'!AJ54),'Haq — Monthly P&L and cash'!L5<'Model inputs'!AJ54,IF(OR('Haq — Monthly P&L and cash'!L5="",'Model inputs'!AJ54=""),"",'Haq — Monthly P&L and cash'!L5<'Model inputs'!AJ54))),IF('Model inputs'!AJ87="","",'Model inputs'!AJ87),IF(IF(IF(ISERROR('Haq — Monthly P&L and cash'!L5<'Model inputs'!AJ84),'Haq — Monthly P&L and cash'!L5<'Model inputs'!AJ84,IF(OR('Haq — Monthly P&L and cash'!L5="",'Model inputs'!AJ84=""),"",'Haq — Monthly P&L and cash'!L5<'Model inputs'!AJ84))="",FALSE,IF(ISERROR('Haq — Monthly P&L and cash'!L5<'Model inputs'!AJ84),'Haq — Monthly P&L and cash'!L5<'Model inputs'!AJ84,IF(OR('Haq — Monthly P&L and cash'!L5="",'Model inputs'!AJ84=""),"",'Haq — Monthly P&L and cash'!L5<'Model inputs'!AJ84))),IF('Model inputs'!AJ55="","",'Model inputs'!AJ55),IF('Model inputs'!AJ85="","",'Model inputs'!AJ85))) -> 4 | M6: =IF(IF(IF(ISERROR('Haq — Monthly P&L and cash'!M5<'Model inputs'!AJ54),'Haq — Monthly P&L and cash'!M5<'Model inputs'!AJ54,IF(OR('Haq — Monthly P&L and cash'!M5="",'Model inputs'!AJ54=""),"",'Haq — Monthly P&L and cash'!M5<'Model inputs'!AJ54))="",FALSE,IF(ISERROR('Haq — Monthly P&L and cash'!M5<'Model inputs'!AJ54),'Haq — Monthly P&L and cash'!M5<'Model inputs'!AJ54,IF(OR('Haq — Monthly P&L and cash'!M5="",'Model inputs'!AJ54=""),"",'Haq — Monthly P&L and cash'!M5<'Model inputs'!AJ54))),IF('Model inputs'!AJ87="","",'Model inputs'!AJ87),IF(IF(IF(ISERROR('Haq — Monthly P&L and cash'!M5<'Model inputs'!AJ84),'Haq — Monthly P&L and cash'!M5<'Model inputs'!AJ84,IF(OR('Haq — Monthly P&L and cash'!M5="",'Model inputs'!AJ84=""),"",'Haq — Monthly P&L and cash'!M5<'Model inputs'!AJ84))="",FALSE,IF(ISERROR('Haq — Monthly P&L and cash'!M5<'Model inputs'!AJ84),'Haq — Monthly P&L and cash'!M5<'Model inputs'!AJ84,IF(OR('Haq — Monthly P&L and cash'!M5="",'Model inputs'!AJ84=""),"",'Haq — Monthly P&L and cash'!M5<'Model inputs'!AJ84))),IF('Model inputs'!AJ55="","",'Model inputs'!AJ55),IF('Model inputs'!AJ85="","",'Model inputs'!AJ85))) -> 4 | N6: =IF(IF(IF(ISERROR('Haq — Monthly P&L and cash'!N5<'Model inputs'!AJ54),'Haq — Monthly P&L and cash'!N5<'Model inputs'!AJ54,IF(OR('Haq — Monthly P&L and cash'!N5="",'Model inputs'!AJ54=""),"",'Haq — Monthly P&L and cash'!N5<'Model inputs'!AJ54))="",FALSE,IF(ISERROR('Haq — Monthly P&L and cash'!N5<'Model inputs'!AJ54),'Haq — Monthly P&L and cash'!N5<'Model inputs'!AJ54,IF(OR('Haq — Monthly P&L and cash'!N5="",'Model inputs'!AJ54=""),"",'Haq — Monthly P&L and cash'!N5<'Model inputs'!AJ54))),IF('Model inputs'!AJ87="","",'Model inputs'!AJ87),IF(IF(IF(ISERROR('Haq — Monthly P&L and cash'!N5<'Model inputs'!AJ84),'Haq — Monthly P&L and cash'!N5<'Model inputs'!AJ84,IF(OR('Haq — Monthly P&L and cash'!N5="",'Model inputs'!AJ84=""),"",'Haq — Monthly P&L and cash'!N5<'Model inputs'!AJ84))="",FALSE,IF(ISERROR('Haq — Monthly P&L and cash'!N5<'Model inputs'!AJ84),'Haq — Monthly P&L and cash'!N5<'Model inputs'!AJ84,IF(OR('Haq — Monthly P&L and cash'!N5="",'Model inputs'!AJ84=""),"",'Haq — Monthly P&L and cash'!N5<'Model inputs'!AJ84))),IF('Model inputs'!AJ55="","",'Model inputs'!AJ55),IF('Model inputs'!AJ85="","",'Model inputs'!AJ85))) -> 4 | O6: =IF(IF(IF(ISERROR('Haq — Monthly P&L and cash'!O5<'Model inputs'!AJ54),'Haq — Monthly P&L and cash'!O5<'Model inputs'!AJ54,IF(OR('Haq — Monthly P&L and cash'!O5="",'Model inputs'!AJ54=""),"",'Haq — Monthly P&L and cash'!O5<'Model inputs'!AJ54))="",FALSE,IF(ISERROR('Haq — Monthly P&L and cash'!O5<'Model inputs'!AJ54),'Haq — Monthly P&L and cash'!O5<'Model inputs'!AJ54,IF(OR('Haq — Monthly P&L and cash'!O5="",'Model inputs'!AJ54=""),"",'Haq — Monthly P&L and cash'!O5<'Model inputs'!AJ54))),IF('Model inputs'!AJ87="","",'Model inputs'!AJ87),IF(IF(IF(ISERROR('Haq — Monthly P&L and cash'!O5<'Model inputs'!AJ84),'Haq — Monthly P&L and cash'!O5<'Model inputs'!AJ84,IF(OR('Haq — Monthly P&L and cash'!O5="",'Model inputs'!AJ84=""),"",'Haq — Monthly P&L and cash'!O5<'Model inputs'!AJ84))="",FALSE,IF(ISERROR('Haq — Monthly P&L and cash'!O5<'Model inputs'!AJ84),'Haq — Monthly P&L and cash'!O5<'Model inputs'!AJ84,IF(OR('Haq — Monthly P&L and cash'!O5="",'Model inputs'!AJ84=""),"",'Haq — Monthly P&L and cash'!O5<'Model inputs'!AJ84))),IF('Model inputs'!AJ55="","",'Model inputs'!AJ55),IF('Model inputs'!AJ85="","",'Model inputs'!AJ85))) -> 4 | P6: =IF(IF(IF(ISERROR('Haq — Monthly P&L and cash'!P5<'Model inputs'!AJ54),'Haq — Monthly P&L and cash'!P5<'Model inputs'!AJ54,IF(OR('Haq — Monthly P&L and cash'!P5="",'Model inputs'!AJ54=""),"",'Haq — Monthly P&L and cash'!P5<'Model inputs'!AJ54))="",FALSE,IF(ISERROR('Haq — Monthly P&L and cash'!P5<'Model inputs'!AJ54),'Haq — Monthly P&L and cash'!P5<'Model inputs'!AJ54,IF(OR('Haq — Monthly P&L and cash'!P5="",'Model inputs'!AJ54=""),"",'Haq — Monthly P&L and cash'!P5<'Model inputs'!AJ54))),IF('Model inputs'!AJ87="","",'Model inputs'!AJ87),IF(IF(IF(ISERROR('Haq — Monthly P&L and cash'!P5<'Model inputs'!AJ84),'Haq — Monthly P&L and cash'!P5<'Model inputs'!AJ84,IF(OR('Haq — Monthly P&L and cash'!P5="",'Model inputs'!AJ84=""),"",'Haq — Monthly P&L and cash'!P5<'Model inputs'!AJ84))="",FALSE,IF(ISERROR('Haq — Monthly P&L and cash'!P5<'Model inputs'!AJ84),'Haq — Monthly P&L and cash'!P5<'Model inputs'!AJ84,IF(OR('Haq — Monthly P&L and cash'!P5="",'Model inputs'!AJ84=""),"",'Haq — Monthly P&L and cash'!P5<'Model inputs'!AJ84))),IF('Model inputs'!AJ55="","",'Model inputs'!AJ55),IF('Model inputs'!AJ85="","",'Model inputs'!AJ85))) -> 4 | Q6: =IF(IF(IF(ISERROR('Haq — Monthly P&L and cash'!Q5<'Model inputs'!AJ54),'Haq — Monthly P&L and cash'!Q5<'Model inputs'!AJ54,IF(OR('Haq — Monthly P&L and cash'!Q5="",'Model inputs'!AJ54=""),"",'Haq — Monthly P&L and cash'!Q5<'Model inputs'!AJ54))="",FALSE,IF(ISERROR('Haq — Monthly P&L and cash'!Q5<'Model inputs'!AJ54),'Haq — Monthly P&L and cash'!Q5<'Model inputs'!AJ54,IF(OR('Haq — Monthly P&L and cash'!Q5="",'Model inputs'!AJ54=""),"",'Haq — Monthly P&L and cash'!Q5<'Model inputs'!AJ54))),IF('Model inputs'!AJ87="","",'Model inputs'!AJ87),IF(IF(IF(ISERROR('Haq — Monthly P&L and cash'!Q5<'Model inputs'!AJ84),'Haq — Monthly P&L and cash'!Q5<'Model inputs'!AJ84,IF(OR('Haq — Monthly P&L and cash'!Q5="",'Model inputs'!AJ84=""),"",'Haq — Monthly P&L and cash'!Q5<'Model inputs'!AJ84))="",FALSE,IF(ISERROR('Haq — Monthly P&L and cash'!Q5<'Model inputs'!AJ84),'Haq — Monthly P&L and cash'!Q5<'Model inputs'!AJ84,IF(OR('Haq — Monthly P&L and cash'!Q5="",'Model inputs'!AJ84=""),"",'Haq — Monthly P&L and cash'!Q5<'Model inputs'!AJ84))),IF('Model inputs'!AJ55="","",'Model inputs'!AJ55),IF('Model inputs'!AJ85="","",'Model inputs'!AJ85))) -> 4 | R6: =IF(IF(IF(ISERROR('Haq — Monthly P&L and cash'!R5<'Model inputs'!AJ54),'Haq — Monthly P&L and cash'!R5<'Model inputs'!AJ54,IF(OR('Haq — Monthly P&L and cash'!R5="",'Model inputs'!AJ54=""),"",'Haq — Monthly P&L and cash'!R5<'Model inputs'!AJ54))="",FALSE,IF(ISERROR('Haq — Monthly P&L and cash'!R5<'Model inputs'!AJ54),'Haq — Monthly P&L and cash'!R5<'Model inputs'!AJ54,IF(OR('Haq — Monthly P&L and cash'!R5="",'Model inputs'!AJ54=""),"",'Haq — Monthly P&L and cash'!R5<'Model inputs'!AJ54))),IF('Model inputs'!AJ87="","",'Model inputs'!AJ87),IF(IF(IF(ISERROR('Haq — Monthly P&L and cash'!R5<'Model inputs'!AJ84),'Haq — Monthly P&L and cash'!R5<'Model inputs'!AJ84,IF(OR('Haq — Monthly P&L and cash'!R5="",'Model inputs'!AJ84=""),"",'Haq — Monthly P&L and cash'!R5<'Model inputs'!AJ84))="",FALSE,IF(ISERROR('Haq — Monthly P&L and cash'!R5<'Model inputs'!AJ84),'Haq — Monthly P&L and cash'!R5<'Model inputs'!AJ84,IF(OR('Haq — Monthly P&L and cash'!R5="",'Model inputs'!AJ84=""),"",'Haq — Monthly P&L and cash'!R5<'Model inputs'!AJ84))),IF('Model inputs'!AJ55="","",'Model inputs'!AJ55),IF('Model inputs'!AJ85="","",'Model inputs'!AJ85))) -> 4 | S6: =IF(IF(IF(ISERROR('Haq — Monthly P&L and cash'!S5<'Model inputs'!AJ54),'Haq — Monthly P&L and cash'!S5<'Model inputs'!AJ54,IF(OR('Haq — Monthly P&L and cash'!S5="",'Model inputs'!AJ54=""),"",'Haq — Monthly P&L and cash'!S5<'Model inputs'!AJ54))="",FALSE,IF(ISERROR('Haq — Monthly P&L and cash'!S5<'Model inputs'!AJ54),'Haq — Monthly P&L and cash'!S5<'Model inputs'!AJ54,IF(OR('Haq — Monthly P&L and cash'!S5="",'Model inputs'!AJ54=""),"",'Haq — Monthly P&L and cash'!S5<'Model inputs'!AJ54))),IF('Model inputs'!AJ87="","",'Model inputs'!AJ87),IF(IF(IF(ISERROR('Haq — Monthly P&L and cash'!S5<'Model inputs'!AJ84),'Haq — Monthly P&L and cash'!S5<'Model inputs'!AJ84,IF(OR('Haq — Monthly P&L and cash'!S5="",'Model inputs'!AJ84=""),"",'Haq — Monthly P&L and cash'!S5<'Model inputs'!AJ84))="",FALSE,IF(ISERROR('Haq — Monthly P&L and cash'!S5<'Model inputs'!AJ84),'Haq — Monthly P&L and cash'!S5<'Model inputs'!AJ84,IF(OR('Haq — Monthly P&L and cash'!S5="",'Model inputs'!AJ84=""),"",'Haq — Monthly P&L and cash'!S5<'Model inputs'!AJ84))),IF('Model inputs'!AJ55="","",'Model inputs'!AJ55),IF('Model inputs'!AJ85="","",'Model inputs'!AJ85))) -> 4 | T6: =IF(IF(IF(ISERROR('Haq — Monthly P&L and cash'!T5<'Model inputs'!AJ54),'Haq — Monthly P&L and cash'!T5<'Model inputs'!AJ54,IF(OR('Haq — Monthly P&L and cash'!T5="",'Model inputs'!AJ54=""),"",'Haq — Monthly P&L and cash'!T5<'Model inputs'!AJ54))="",FALSE,IF(ISERROR('Haq — Monthly P&L and cash'!T5<'Model inputs'!AJ54),'Haq — Monthly P&L and cash'!T5<'Model inputs'!AJ54,IF(OR('Haq — Monthly P&L and cash'!T5="",'Model inputs'!AJ54=""),"",'Haq — Monthly P&L and cash'!T5<'Model inputs'!AJ54))),IF('Model inputs'!AJ87="","",'Model inputs'!AJ87),IF(IF(IF(ISERROR('Haq — Monthly P&L and cash'!T5<'Model inputs'!AJ84),'Haq — Monthly P&L and cash'!T5<'Model inputs'!AJ84,IF(OR('Haq — Monthly P&L and cash'!T5="",'Model inputs'!AJ84=""),"",'Haq — Monthly P&L and cash'!T5<'Model inputs'!AJ84))="",FALSE,IF(ISERROR('Haq — Monthly P&L and cash'!T5<'Model inputs'!AJ84),'Haq — Monthly P&L and cash'!T5<'Model inputs'!AJ84,IF(OR('Haq — Monthly P&L and cash'!T5="",'Model inputs'!AJ84=""),"",'Haq — Monthly P&L and cash'!T5<'Model inputs'!AJ84))),IF('Model inputs'!AJ55="","",'Model inputs'!AJ55),IF('Model inputs'!AJ85="","",'Model inputs'!AJ85))) -> 4 | U6: =IF(IF(IF(ISERROR('Haq — Monthly P&L and cash'!U5<'Model inputs'!AJ54),'Haq — Monthly P&L and cash'!U5<'Model inputs'!AJ54,IF(OR('Haq — Monthly P&L and cash'!U5="",'Model inputs'!AJ54=""),"",'Haq — Monthly P&L and cash'!U5<'Model inputs'!AJ54))="",FALSE,IF(ISERROR('Haq — Monthly P&L and cash'!U5<'Model inputs'!AJ54),'Haq — Monthly P&L and cash'!U5<'Model inputs'!AJ54,IF(OR('Haq — Monthly P&L and cash'!U5="",'Model inputs'!AJ54=""),"",'Haq — Monthly P&L and cash'!U5<'Model inputs'!AJ54))),IF('Model inputs'!AJ87="","",'Model inputs'!AJ87),IF(IF(IF(ISERROR('Haq — Monthly P&L and cash'!U5<'Model inputs'!AJ84),'Haq — Monthly P&L and cash'!U5<'Model inputs'!AJ84,IF(OR('Haq — Monthly P&L and cash'!U5="",'Model inputs'!AJ84=""),"",'Haq — Monthly P&L and cash'!U5<'Model inputs'!AJ84))="",FALSE,IF(ISERROR('Haq — Monthly P&L and cash'!U5<'Model inputs'!AJ84),'Haq — Monthly P&L and cash'!U5<'Model inputs'!AJ84,IF(OR('Haq — Monthly P&L and cash'!U5="",'Model inputs'!AJ84=""),"",'Haq — Monthly P&L and cash'!U5<'Model inputs'!AJ84))),IF('Model inputs'!AJ55="","",'Model inputs'!AJ55),IF('Model inputs'!AJ85="","",'Model inputs'!AJ85))) -> 4 | V6: =IF(IF(IF(ISERROR('Haq — Monthly P&L and cash'!V5<'Model inputs'!AJ54),'Haq — Monthly P&L and cash'!V5<'Model inputs'!AJ54,IF(OR('Haq — Monthly P&L and cash'!V5="",'Model inputs'!AJ54=""),"",'Haq — Monthly P&L and cash'!V5<'Model inputs'!AJ54))="",FALSE,IF(ISERROR('Haq — Monthly P&L and cash'!V5<'Model inputs'!AJ54),'Haq — Monthly P&L and cash'!V5<'Model inputs'!AJ54,IF(OR('Haq — Monthly P&L and cash'!V5="",'Model inputs'!AJ54=""),"",'Haq — Monthly P&L and cash'!V5<'Model inputs'!AJ54))),IF('Model inputs'!AJ87="","",'Model inputs'!AJ87),IF(IF(IF(ISERROR('Haq — Monthly P&L and cash'!V5<'Model inputs'!AJ84),'Haq — Monthly P&L and cash'!V5<'Model inputs'!AJ84,IF(OR('Haq — Monthly P&L and cash'!V5="",'Model inputs'!AJ84=""),"",'Haq — Monthly P&L and cash'!V5<'Model inputs'!AJ84))="",FALSE,IF(ISERROR('Haq — Monthly P&L and cash'!V5<'Model inputs'!AJ84),'Haq — Monthly P&L and cash'!V5<'Model inputs'!AJ84,IF(OR('Haq — Monthly P&L and cash'!V5="",'Model inputs'!AJ84=""),"",'Haq — Monthly P&L and cash'!V5<'Model inputs'!AJ84))),IF('Model inputs'!AJ55="","",'Model inputs'!AJ55),IF('Model inputs'!AJ85="","",'Model inputs'!AJ85))) -> 4 | W6: =IF(IF(IF(ISERROR('Haq — Monthly P&L and cash'!W5<'Model inputs'!AJ54),'Haq — Monthly P&L and cash'!W5<'Model inputs'!AJ54,IF(OR('Haq — Monthly P&L and cash'!W5="",'Model inputs'!AJ54=""),"",'Haq — Monthly P&L and cash'!W5<'Model inputs'!AJ54))="",FALSE,IF(ISERROR('Haq — Monthly P&L and cash'!W5<'Model inputs'!AJ54),'Haq — Monthly P&L and cash'!W5<'Model inputs'!AJ54,IF(OR('Haq — Monthly P&L and cash'!W5="",'Model inputs'!AJ54=""),"",'Haq — Monthly P&L and cash'!W5<'Model inputs'!AJ54))),IF('Model inputs'!AJ87="","",'Model inputs'!AJ87),IF(IF(IF(ISERROR('Haq — Monthly P&L and cash'!W5<'Model inputs'!AJ84),'Haq — Monthly P&L and cash'!W5<'Model inputs'!AJ84,IF(OR('Haq — Monthly P&L and cash'!W5="",'Model inputs'!AJ84=""),"",'Haq — Monthly P&L and cash'!W5<'Model inputs'!AJ84))="",FALSE,IF(ISERROR('Haq — Monthly P&L and cash'!W5<'Model inputs'!AJ84),'Haq — Monthly P&L and cash'!W5<'Model inputs'!AJ84,IF(OR('Haq — Monthly P&L and cash'!W5="",'Model inputs'!AJ84=""),"",'Haq — Monthly P&L and cash'!W5<'Model inputs'!AJ84))),IF('Model inputs'!AJ55="","",'Model inputs'!AJ55),IF('Model inputs'!AJ85="","",'Model inputs'!AJ85))) -> 4 | X6: =IF(IF(IF(ISERROR('Haq — Monthly P&L and cash'!X5<'Model inputs'!AJ54),'Haq — Monthly P&L and cash'!X5<'Model inputs'!AJ54,IF(OR('Haq — Monthly P&L and cash'!X5="",'Model inputs'!AJ54=""),"",'Haq — Monthly P&L and cash'!X5<'Model inputs'!AJ54))="",FALSE,IF(ISERROR('Haq — Monthly P&L and cash'!X5<'Model inputs'!AJ54),'Haq — Monthly P&L and cash'!X5<'Model inputs'!AJ54,IF(OR('Haq — Monthly P&L and cash'!X5="",'Model inputs'!AJ54=""),"",'Haq — Monthly P&L and cash'!X5<'Model inputs'!AJ54))),IF('Model inputs'!AJ87="","",'Model inputs'!AJ87),IF(IF(IF(ISERROR('Haq — Monthly P&L and cash'!X5<'Model inputs'!AJ84),'Haq — Monthly P&L and cash'!X5<'Model inputs'!AJ84,IF(OR('Haq — Monthly P&L and cash'!X5="",'Model inputs'!AJ84=""),"",'Haq — Monthly P&L and cash'!X5<'Model inputs'!AJ84))="",FALSE,IF(ISERROR('Haq — Monthly P&L and cash'!X5<'Model inputs'!AJ84),'Haq — Monthly P&L and cash'!X5<'Model inputs'!AJ84,IF(OR('Haq — Monthly P&L and cash'!X5="",'Model inputs'!AJ84=""),"",'Haq — Monthly P&L and cash'!X5<'Model inputs'!AJ84))),IF('Model inputs'!AJ55="","",'Model inputs'!AJ55),IF('Model inputs'!AJ85="","",'Model inputs'!AJ85))) -> 4 | Y6: =IF(IF(IF(ISERROR('Haq — Monthly P&L and cash'!Y5<'Model inputs'!AJ54),'Haq — Monthly P&L and cash'!Y5<'Model inputs'!AJ54,IF(OR('Haq — Monthly P&L and cash'!Y5="",'Model inputs'!AJ54=""),"",'Haq — Monthly P&L and cash'!Y5<'Model inputs'!AJ54))="",FALSE,IF(ISERROR('Haq — Monthly P&L and cash'!Y5<'Model inputs'!AJ54),'Haq — Monthly P&L and cash'!Y5<'Model inputs'!AJ54,IF(OR('Haq — Monthly P&L and cash'!Y5="",'Model inputs'!AJ54=""),"",'Haq — Monthly P&L and cash'!Y5<'Model inputs'!AJ54))),IF('Model inputs'!AJ87="","",'Model inputs'!AJ87),IF(IF(IF(ISERROR('Haq — Monthly P&L and cash'!Y5<'Model inputs'!AJ84),'Haq — Monthly P&L and cash'!Y5<'Model inputs'!AJ84,IF(OR('Haq — Monthly P&L and cash'!Y5="",'Model inputs'!AJ84=""),"",'Haq — Monthly P&L and cash'!Y5<'Model inputs'!AJ84))="",FALSE,IF(ISERROR('Haq — Monthly P&L and cash'!Y5<'Model inputs'!AJ84),'Haq — Monthly P&L and cash'!Y5<'Model inputs'!AJ84,IF(OR('Haq — Monthly P&L and cash'!Y5="",'Model inputs'!AJ84=""),"",'Haq — Monthly P&L and cash'!Y5<'Model inputs'!AJ84))),IF('Model inputs'!AJ55="","",'Model inputs'!AJ55),IF('Model inputs'!AJ85="","",'Model inputs'!AJ85))) -> 4
A7: Haq CSC operators | B7: =IF(IF(IF(ISERROR('Haq — Monthly P&L and cash'!B5<'Model inputs'!AJ40),'Haq — Monthly P&L and cash'!B5<'Model inputs'!AJ40,IF(OR('Haq — Monthly P&L and cash'!B5="",'Model inputs'!AJ40=""),"",'Haq — Monthly P&L and cash'!B5<'Model inputs'!AJ40))="",FALSE,IF(ISERROR('Haq — Monthly P&L and cash'!B5<'Model inputs'!AJ40),'Haq — Monthly P&L and cash'!B5<'Model inputs'!AJ40,IF(OR('Haq — Monthly P&L and cash'!B5="",'Model inputs'!AJ40=""),"",'Haq — Monthly P&L and cash'!B5<'Model inputs'!AJ40))),0,IF(IF(IF(ISERROR('Haq — Monthly P&L and cash'!B5='Model inputs'!AJ40),'Haq — Monthly P&L and cash'!B5='Model inputs'!AJ40,IF(OR('Haq — Monthly P&L and cash'!B5="",'Model inputs'!AJ40=""),"",'Haq — Monthly P&L and cash'!B5='Model inputs'!AJ40))="",FALSE,IF(ISERROR('Haq — Monthly P&L and cash'!B5='Model inputs'!AJ40),'Haq — Monthly P&L and cash'!B5='Model inputs'!AJ40,IF(OR('Haq — Monthly P&L and cash'!B5="",'Model inputs'!AJ40=""),"",'Haq — Monthly P&L and cash'!B5='Model inputs'!AJ40))),IF('Model inputs'!AJ41="","",'Model inputs'!AJ41),'Model inputs'!C14*(1+'Model inputs'!AJ37-'Model inputs'!AJ42))) -> 0 | C7: =IF(IF(IF(ISERROR('Haq — Monthly P&L and cash'!C5<'Model inputs'!AJ40),'Haq — Monthly P&L and cash'!C5<'Model inputs'!AJ40,IF(OR('Haq — Monthly P&L and cash'!C5="",'Model inputs'!AJ40=""),"",'Haq — Monthly P&L and cash'!C5<'Model inputs'!AJ40))="",FALSE,IF(ISERROR('Haq — Monthly P&L and cash'!C5<'Model inputs'!AJ40),'Haq — Monthly P&L and cash'!C5<'Model inputs'!AJ40,IF(OR('Haq — Monthly P&L and cash'!C5="",'Model inputs'!AJ40=""),"",'Haq — Monthly P&L and cash'!C5<'Model inputs'!AJ40))),0,IF(IF(IF(ISERROR('Haq — Monthly P&L and cash'!C5='Model inputs'!AJ40),'Haq — Monthly P&L and cash'!C5='Model inputs'!AJ40,IF(OR('Haq — Monthly P&L and cash'!C5="",'Model inputs'!AJ40=""),"",'Haq — Monthly P&L and cash'!C5='Model inputs'!AJ40))="",FALSE,IF(ISERROR('Haq — Monthly P&L and cash'!C5='Model inputs'!AJ40),'Haq — Monthly P&L and cash'!C5='Model inputs'!AJ40,IF(OR('Haq — Monthly P&L and cash'!C5="",'Model inputs'!AJ40=""),"",'Haq — Monthly P&L and cash'!C5='Model inputs'!AJ40))),IF('Model inputs'!AJ41="","",'Model inputs'!AJ41),'Haq — Monthly P&L and cash'!B7*(1+'Model inputs'!AJ37-'Model inputs'!AJ42))) -> 0 | D7: =IF(IF(IF(ISERROR('Haq — Monthly P&L and cash'!D5<'Model inputs'!AJ40),'Haq — Monthly P&L and cash'!D5<'Model inputs'!AJ40,IF(OR('Haq — Monthly P&L and cash'!D5="",'Model inputs'!AJ40=""),"",'Haq — Monthly P&L and cash'!D5<'Model inputs'!AJ40))="",FALSE,IF(ISERROR('Haq — Monthly P&L and cash'!D5<'Model inputs'!AJ40),'Haq — Monthly P&L and cash'!D5<'Model inputs'!AJ40,IF(OR('Haq — Monthly P&L and cash'!D5="",'Model inputs'!AJ40=""),"",'Haq — Monthly P&L and cash'!D5<'Model inputs'!AJ40))),0,IF(IF(IF(ISERROR('Haq — Monthly P&L and cash'!D5='Model inputs'!AJ40),'Haq — Monthly P&L and cash'!D5='Model inputs'!AJ40,IF(OR('Haq — Monthly P&L and cash'!D5="",'Model inputs'!AJ40=""),"",'Haq — Monthly P&L and cash'!D5='Model inputs'!AJ40))="",FALSE,IF(ISERROR('Haq — Monthly P&L and cash'!D5='Model inputs'!AJ40),'Haq — Monthly P&L and cash'!D5='Model inputs'!AJ40,IF(OR('Haq — Monthly P&L and cash'!D5="",'Model inputs'!AJ40=""),"",'Haq — Monthly P&L and cash'!D5='Model inputs'!AJ40))),IF('Model inputs'!AJ41="","",'Model inputs'!AJ41),'Haq — Monthly P&L and cash'!C7*(1+'Model inputs'!AJ37-'Model inputs'!AJ42))) -> 0 | E7: =IF(IF(IF(ISERROR('Haq — Monthly P&L and cash'!E5<'Model inputs'!AJ40),'Haq — Monthly P&L and cash'!E5<'Model inputs'!AJ40,IF(OR('Haq — Monthly P&L and cash'!E5="",'Model inputs'!AJ40=""),"",'Haq — Monthly P&L and cash'!E5<'Model inputs'!AJ40))="",FALSE,IF(ISERROR('Haq — Monthly P&L and cash'!E5<'Model inputs'!AJ40),'Haq — Monthly P&L and cash'!E5<'Model inputs'!AJ40,IF(OR('Haq — Monthly P&L and cash'!E5="",'Model inputs'!AJ40=""),"",'Haq — Monthly P&L and cash'!E5<'Model inputs'!AJ40))),0,IF(IF(IF(ISERROR('Haq — Monthly P&L and cash'!E5='Model inputs'!AJ40),'Haq — Monthly P&L and cash'!E5='Model inputs'!AJ40,IF(OR('Haq — Monthly P&L and cash'!E5="",'Model inputs'!AJ40=""),"",'Haq — Monthly P&L and cash'!E5='Model inputs'!AJ40))="",FALSE,IF(ISERROR('Haq — Monthly P&L and cash'!E5='Model inputs'!AJ40),'Haq — Monthly P&L and cash'!E5='Model inputs'!AJ40,IF(OR('Haq — Monthly P&L and cash'!E5="",'Model inputs'!AJ40=""),"",'Haq — Monthly P&L and cash'!E5='Model inputs'!AJ40))),IF('Model inputs'!AJ41="","",'Model inputs'!AJ41),'Haq — Monthly P&L and cash'!D7*(1+'Model inputs'!AJ37-'Model inputs'!AJ42))) -> 50 | F7: =IF(IF(IF(ISERROR('Haq — Monthly P&L and cash'!F5<'Model inputs'!AJ40),'Haq — Monthly P&L and cash'!F5<'Model inputs'!AJ40,IF(OR('Haq — Monthly P&L and cash'!F5="",'Model inputs'!AJ40=""),"",'Haq — Monthly P&L and cash'!F5<'Model inputs'!AJ40))="",FALSE,IF(ISERROR('Haq — Monthly P&L and cash'!F5<'Model inputs'!AJ40),'Haq — Monthly P&L and cash'!F5<'Model inputs'!AJ40,IF(OR('Haq — Monthly P&L and cash'!F5="",'Model inputs'!AJ40=""),"",'Haq — Monthly P&L and cash'!F5<'Model inputs'!AJ40))),0,IF(IF(IF(ISERROR('Haq — Monthly P&L and cash'!F5='Model inputs'!AJ40),'Haq — Monthly P&L and cash'!F5='Model inputs'!AJ40,IF(OR('Haq — Monthly P&L and cash'!F5="",'Model inputs'!AJ40=""),"",'Haq — Monthly P&L and cash'!F5='Model inputs'!AJ40))="",FALSE,IF(ISERROR('Haq — Monthly P&L and cash'!F5='Model inputs'!AJ40),'Haq — Monthly P&L and cash'!F5='Model inputs'!AJ40,IF(OR('Haq — Monthly P&L and cash'!F5="",'Model inputs'!AJ40=""),"",'Haq — Monthly P&L and cash'!F5='Model inputs'!AJ40))),IF('Model inputs'!AJ41="","",'Model inputs'!AJ41),'Haq — Monthly P&L and cash'!E7*(1+'Model inputs'!AJ37-'Model inputs'!AJ42))) -> 57.5 | G7: =IF(IF(IF(ISERROR('Haq — Monthly P&L and cash'!G5<'Model inputs'!AJ40),'Haq — Monthly P&L and cash'!G5<'Model inputs'!AJ40,IF(OR('Haq — Monthly P&L and cash'!G5="",'Model inputs'!AJ40=""),"",'Haq — Monthly P&L and cash'!G5<'Model inputs'!AJ40))="",FALSE,IF(ISERROR('Haq — Monthly P&L and cash'!G5<'Model inputs'!AJ40),'Haq — Monthly P&L and cash'!G5<'Model inputs'!AJ40,IF(OR('Haq — Monthly P&L and cash'!G5="",'Model inputs'!AJ40=""),"",'Haq — Monthly P&L and cash'!G5<'Model inputs'!AJ40))),0,IF(IF(IF(ISERROR('Haq — Monthly P&L and cash'!G5='Model inputs'!AJ40),'Haq — Monthly P&L and cash'!G5='Model inputs'!AJ40,IF(OR('Haq — Monthly P&L and cash'!G5="",'Model inputs'!AJ40=""),"",'Haq — Monthly P&L and cash'!G5='Model inputs'!AJ40))="",FALSE,IF(ISERROR('Haq — Monthly P&L and cash'!G5='Model inputs'!AJ40),'Haq — Monthly P&L and cash'!G5='Model inputs'!AJ40,IF(OR('Haq — Monthly P&L and cash'!G5="",'Model inputs'!AJ40=""),"",'Haq — Monthly P&L and cash'!G5='Model inputs'!AJ40))),IF('Model inputs'!AJ41="","",'Model inputs'!AJ41),'Haq — Monthly P&L and cash'!F7*(1+'Model inputs'!AJ37-'Model inputs'!AJ42))) -> 66.125 | H7: =IF(IF(IF(ISERROR('Haq — Monthly P&L and cash'!H5<'Model inputs'!AJ40),'Haq — Monthly P&L and cash'!H5<'Model inputs'!AJ40,IF(OR('Haq — Monthly P&L and cash'!H5="",'Model inputs'!AJ40=""),"",'Haq — Monthly P&L and cash'!H5<'Model inputs'!AJ40))="",FALSE,IF(ISERROR('Haq — Monthly P&L and cash'!H5<'Model inputs'!AJ40),'Haq — Monthly P&L and cash'!H5<'Model inputs'!AJ40,IF(OR('Haq — Monthly P&L and cash'!H5="",'Model inputs'!AJ40=""),"",'Haq — Monthly P&L and cash'!H5<'Model inputs'!AJ40))),0,IF(IF(IF(ISERROR('Haq — Monthly P&L and cash'!H5='Model inputs'!AJ40),'Haq — Monthly P&L and cash'!H5='Model inputs'!AJ40,IF(OR('Haq — Monthly P&L and cash'!H5="",'Model inputs'!AJ40=""),"",'Haq — Monthly P&L and cash'!H5='Model inputs'!AJ40))="",FALSE,IF(ISERROR('Haq — Monthly P&L and cash'!H5='Model inputs'!AJ40),'Haq — Monthly P&L and cash'!H5='Model inputs'!AJ40,IF(OR('Haq — Monthly P&L and cash'!H5="",'Model inputs'!AJ40=""),"",'Haq — Monthly P&L and cash'!H5='Model inputs'!AJ40))),IF('Model inputs'!AJ41="","",'Model inputs'!AJ41),'Haq — Monthly P&L and cash'!G7*(1+'Model inputs'!AJ37-'Model inputs'!AJ42))) -> 76.04375 | I7: =IF(IF(IF(ISERROR('Haq — Monthly P&L and cash'!I5<'Model inputs'!AJ40),'Haq — Monthly P&L and cash'!I5<'Model inputs'!AJ40,IF(OR('Haq — Monthly P&L and cash'!I5="",'Model inputs'!AJ40=""),"",'Haq — Monthly P&L and cash'!I5<'Model inputs'!AJ40))="",FALSE,IF(ISERROR('Haq — Monthly P&L and cash'!I5<'Model inputs'!AJ40),'Haq — Monthly P&L and cash'!I5<'Model inputs'!AJ40,IF(OR('Haq — Monthly P&L and cash'!I5="",'Model inputs'!AJ40=""),"",'Haq — Monthly P&L and cash'!I5<'Model inputs'!AJ40))),0,IF(IF(IF(ISERROR('Haq — Monthly P&L and cash'!I5='Model inputs'!AJ40),'Haq — Monthly P&L and cash'!I5='Model inputs'!AJ40,IF(OR('Haq — Monthly P&L and cash'!I5="",'Model inputs'!AJ40=""),"",'Haq — Monthly P&L and cash'!I5='Model inputs'!AJ40))="",FALSE,IF(ISERROR('Haq — Monthly P&L and cash'!I5='Model inputs'!AJ40),'Haq — Monthly P&L and cash'!I5='Model inputs'!AJ40,IF(OR('Haq — Monthly P&L and cash'!I5="",'Model inputs'!AJ40=""),"",'Haq — Monthly P&L and cash'!I5='Model inputs'!AJ40))),IF('Model inputs'!AJ41="","",'Model inputs'!AJ41),'Haq — Monthly P&L and cash'!H7*(1+'Model inputs'!AJ37-'Model inputs'!AJ42))) -> 87.450312 | J7: =IF(IF(IF(ISERROR('Haq — Monthly P&L and cash'!J5<'Model inputs'!AJ40),'Haq — Monthly P&L and cash'!J5<'Model inputs'!AJ40,IF(OR('Haq — Monthly P&L and cash'!J5="",'Model inputs'!AJ40=""),"",'Haq — Monthly P&L and cash'!J5<'Model inputs'!AJ40))="",FALSE,IF(ISERROR('Haq — Monthly P&L and cash'!J5<'Model inputs'!AJ40),'Haq — Monthly P&L and cash'!J5<'Model inputs'!AJ40,IF(OR('Haq — Monthly P&L and cash'!J5="",'Model inputs'!AJ40=""),"",'Haq — Monthly P&L and cash'!J5<'Model inputs'!AJ40))),0,IF(IF(IF(ISERROR('Haq — Monthly P&L and cash'!J5='Model inputs'!AJ40),'Haq — Monthly P&L and cash'!J5='Model inputs'!AJ40,IF(OR('Haq — Monthly P&L and cash'!J5="",'Model inputs'!AJ40=""),"",'Haq — Monthly P&L and cash'!J5='Model inputs'!AJ40))="",FALSE,IF(ISERROR('Haq — Monthly P&L and cash'!J5='Model inputs'!AJ40),'Haq — Monthly P&L and cash'!J5='Model inputs'!AJ40,IF(OR('Haq — Monthly P&L and cash'!J5="",'Model inputs'!AJ40=""),"",'Haq — Monthly P&L and cash'!J5='Model inputs'!AJ40))),IF('Model inputs'!AJ41="","",'Model inputs'!AJ41),'Haq — Monthly P&L and cash'!I7*(1+'Model inputs'!AJ37-'Model inputs'!AJ42))) -> 100.56786 | K7: =IF(IF(IF(ISERROR('Haq — Monthly P&L and cash'!K5<'Model inputs'!AJ40),'Haq — Monthly P&L and cash'!K5<'Model inputs'!AJ40,IF(OR('Haq — Monthly P&L and cash'!K5="",'Model inputs'!AJ40=""),"",'Haq — Monthly P&L and cash'!K5<'Model inputs'!AJ40))="",FALSE,IF(ISERROR('Haq — Monthly P&L and cash'!K5<'Model inputs'!AJ40),'Haq — Monthly P&L and cash'!K5<'Model inputs'!AJ40,IF(OR('Haq — Monthly P&L and cash'!K5="",'Model inputs'!AJ40=""),"",'Haq — Monthly P&L and cash'!K5<'Model inputs'!AJ40))),0,IF(IF(IF(ISERROR('Haq — Monthly P&L and cash'!K5='Model inputs'!AJ40),'Haq — Monthly P&L and cash'!K5='Model inputs'!AJ40,IF(OR('Haq — Monthly P&L and cash'!K5="",'Model inputs'!AJ40=""),"",'Haq — Monthly P&L and cash'!K5='Model inputs'!AJ40))="",FALSE,IF(ISERROR('Haq — Monthly P&L and cash'!K5='Model inputs'!AJ40),'Haq — Monthly P&L and cash'!K5='Model inputs'!AJ40,IF(OR('Haq — Monthly P&L and cash'!K5="",'Model inputs'!AJ40=""),"",'Haq — Monthly P&L and cash'!K5='Model inputs'!AJ40))),IF('Model inputs'!AJ41="","",'Model inputs'!AJ41),'Haq — Monthly P&L and cash'!J7*(1+'Model inputs'!AJ37-'Model inputs'!AJ42))) -> 115.65304 | L7: =IF(IF(IF(ISERROR('Haq — Monthly P&L and cash'!L5<'Model inputs'!AJ40),'Haq — Monthly P&L and cash'!L5<'Model inputs'!AJ40,IF(OR('Haq — Monthly P&L and cash'!L5="",'Model inputs'!AJ40=""),"",'Haq — Monthly P&L and cash'!L5<'Model inputs'!AJ40))="",FALSE,IF(ISERROR('Haq — Monthly P&L and cash'!L5<'Model inputs'!AJ40),'Haq — Monthly P&L and cash'!L5<'Model inputs'!AJ40,IF(OR('Haq — Monthly P&L and cash'!L5="",'Model inputs'!AJ40=""),"",'Haq — Monthly P&L and cash'!L5<'Model inputs'!AJ40))),0,IF(IF(IF(ISERROR('Haq — Monthly P&L and cash'!L5='Model inputs'!AJ40),'Haq — Monthly P&L and cash'!L5='Model inputs'!AJ40,IF(OR('Haq — Monthly P&L and cash'!L5="",'Model inputs'!AJ40=""),"",'Haq — Monthly P&L and cash'!L5='Model inputs'!AJ40))="",FALSE,IF(ISERROR('Haq — Monthly P&L and cash'!L5='Model inputs'!AJ40),'Haq — Monthly P&L and cash'!L5='Model inputs'!AJ40,IF(OR('Haq — Monthly P&L and cash'!L5="",'Model inputs'!AJ40=""),"",'Haq — Monthly P&L and cash'!L5='Model inputs'!AJ40))),IF('Model inputs'!AJ41="","",'Model inputs'!AJ41),'Haq — Monthly P&L and cash'!K7*(1+'Model inputs'!AJ37-'Model inputs'!AJ42))) -> 133.00099 | M7: =IF(IF(IF(ISERROR('Haq — Monthly P&L and cash'!M5<'Model inputs'!AJ40),'Haq — Monthly P&L and cash'!M5<'Model inputs'!AJ40,IF(OR('Haq — Monthly P&L and cash'!M5="",'Model inputs'!AJ40=""),"",'Haq — Monthly P&L and cash'!M5<'Model inputs'!AJ40))="",FALSE,IF(ISERROR('Haq — Monthly P&L and cash'!M5<'Model inputs'!AJ40),'Haq — Monthly P&L and cash'!M5<'Model inputs'!AJ40,IF(OR('Haq — Monthly P&L and cash'!M5="",'Model inputs'!AJ40=""),"",'Haq — Monthly P&L and cash'!M5<'Model inputs'!AJ40))),0,IF(IF(IF(ISERROR('Haq — Monthly P&L and cash'!M5='Model inputs'!AJ40),'Haq — Monthly P&L and cash'!M5='Model inputs'!AJ40,IF(OR('Haq — Monthly P&L and cash'!M5="",'Model inputs'!AJ40=""),"",'Haq — Monthly P&L and cash'!M5='Model inputs'!AJ40))="",FALSE,IF(ISERROR('Haq — Monthly P&L and cash'!M5='Model inputs'!AJ40),'Haq — Monthly P&L and cash'!M5='Model inputs'!AJ40,IF(OR('Haq — Monthly P&L and cash'!M5="",'Model inputs'!AJ40=""),"",'Haq — Monthly P&L and cash'!M5='Model inputs'!AJ40))),IF('Model inputs'!AJ41="","",'Model inputs'!AJ41),'Haq — Monthly P&L and cash'!L7*(1+'Model inputs'!AJ37-'Model inputs'!AJ42))) -> 152.95114 | N7: =IF(IF(IF(ISERROR('Haq — Monthly P&L and cash'!N5<'Model inputs'!AJ40),'Haq — Monthly P&L and cash'!N5<'Model inputs'!AJ40,IF(OR('Haq — Monthly P&L and cash'!N5="",'Model inputs'!AJ40=""),"",'Haq — Monthly P&L and cash'!N5<'Model inputs'!AJ40))="",FALSE,IF(ISERROR('Haq — Monthly P&L and cash'!N5<'Model inputs'!AJ40),'Haq — Monthly P&L and cash'!N5<'Model inputs'!AJ40,IF(OR('Haq — Monthly P&L and cash'!N5="",'Model inputs'!AJ40=""),"",'Haq — Monthly P&L and cash'!N5<'Model inputs'!AJ40))),0,IF(IF(IF(ISERROR('Haq — Monthly P&L and cash'!N5='Model inputs'!AJ40),'Haq — Monthly P&L and cash'!N5='Model inputs'!AJ40,IF(OR('Haq — Monthly P&L and cash'!N5="",'Model inputs'!AJ40=""),"",'Haq — Monthly P&L and cash'!N5='Model inputs'!AJ40))="",FALSE,IF(ISERROR('Haq — Monthly P&L and cash'!N5='Model inputs'!AJ40),'Haq — Monthly P&L and cash'!N5='Model inputs'!AJ40,IF(OR('Haq — Monthly P&L and cash'!N5="",'Model inputs'!AJ40=""),"",'Haq — Monthly P&L and cash'!N5='Model inputs'!AJ40))),IF('Model inputs'!AJ41="","",'Model inputs'!AJ41),'Haq — Monthly P&L and cash'!M7*(1+'Model inputs'!AJ37-'Model inputs'!AJ42))) -> 175.89381 | O7: =IF(IF(IF(ISERROR('Haq — Monthly P&L and cash'!O5<'Model inputs'!AJ40),'Haq — Monthly P&L and cash'!O5<'Model inputs'!AJ40,IF(OR('Haq — Monthly P&L and cash'!O5="",'Model inputs'!AJ40=""),"",'Haq — Monthly P&L and cash'!O5<'Model inputs'!AJ40))="",FALSE,IF(ISERROR('Haq — Monthly P&L and cash'!O5<'Model inputs'!AJ40),'Haq — Monthly P&L and cash'!O5<'Model inputs'!AJ40,IF(OR('Haq — Monthly P&L and cash'!O5="",'Model inputs'!AJ40=""),"",'Haq — Monthly P&L and cash'!O5<'Model inputs'!AJ40))),0,IF(IF(IF(ISERROR('Haq — Monthly P&L and cash'!O5='Model inputs'!AJ40),'Haq — Monthly P&L and cash'!O5='Model inputs'!AJ40,IF(OR('Haq — Monthly P&L and cash'!O5="",'Model inputs'!AJ40=""),"",'Haq — Monthly P&L and cash'!O5='Model inputs'!AJ40))="",FALSE,IF(ISERROR('Haq — Monthly P&L and cash'!O5='Model inputs'!AJ40),'Haq — Monthly P&L and cash'!O5='Model inputs'!AJ40,IF(OR('Haq — Monthly P&L and cash'!O5="",'Model inputs'!AJ40=""),"",'Haq — Monthly P&L and cash'!O5='Model inputs'!AJ40))),IF('Model inputs'!AJ41="","",'Model inputs'!AJ41),'Haq — Monthly P&L and cash'!N7*(1+'Model inputs'!AJ37-'Model inputs'!AJ42))) -> 202.27789 | P7: =IF(IF(IF(ISERROR('Haq — Monthly P&L and cash'!P5<'Model inputs'!AJ40),'Haq — Monthly P&L and cash'!P5<'Model inputs'!AJ40,IF(OR('Haq — Monthly P&L and cash'!P5="",'Model inputs'!AJ40=""),"",'Haq — Monthly P&L and cash'!P5<'Model inputs'!AJ40))="",FALSE,IF(ISERROR('Haq — Monthly P&L and cash'!P5<'Model inputs'!AJ40),'Haq — Monthly P&L and cash'!P5<'Model inputs'!AJ40,IF(OR('Haq — Monthly P&L and cash'!P5="",'Model inputs'!AJ40=""),"",'Haq — Monthly P&L and cash'!P5<'Model inputs'!AJ40))),0,IF(IF(IF(ISERROR('Haq — Monthly P&L and cash'!P5='Model inputs'!AJ40),'Haq — Monthly P&L and cash'!P5='Model inputs'!AJ40,IF(OR('Haq — Monthly P&L and cash'!P5="",'Model inputs'!AJ40=""),"",'Haq — Monthly P&L and cash'!P5='Model inputs'!AJ40))="",FALSE,IF(ISERROR('Haq — Monthly P&L and cash'!P5='Model inputs'!AJ40),'Haq — Monthly P&L and cash'!P5='Model inputs'!AJ40,IF(OR('Haq — Monthly P&L and cash'!P5="",'Model inputs'!AJ40=""),"",'Haq — Monthly P&L and cash'!P5='Model inputs'!AJ40))),IF('Model inputs'!AJ41="","",'Model inputs'!AJ41),'Haq — Monthly P&L and cash'!O7*(1+'Model inputs'!AJ37-'Model inputs'!AJ42))) -> 232.61957 | Q7: =IF(IF(IF(ISERROR('Haq — Monthly P&L and cash'!Q5<'Model inputs'!AJ40),'Haq — Monthly P&L and cash'!Q5<'Model inputs'!AJ40,IF(OR('Haq — Monthly P&L and cash'!Q5="",'Model inputs'!AJ40=""),"",'Haq — Monthly P&L and cash'!Q5<'Model inputs'!AJ40))="",FALSE,IF(ISERROR('Haq — Monthly P&L and cash'!Q5<'Model inputs'!AJ40),'Haq — Monthly P&L and cash'!Q5<'Model inputs'!AJ40,IF(OR('Haq — Monthly P&L and cash'!Q5="",'Model inputs'!AJ40=""),"",'Haq — Monthly P&L and cash'!Q5<'Model inputs'!AJ40))),0,IF(IF(IF(ISERROR('Haq — Monthly P&L and cash'!Q5='Model inputs'!AJ40),'Haq — Monthly P&L and cash'!Q5='Model inputs'!AJ40,IF(OR('Haq — Monthly P&L and cash'!Q5="",'Model inputs'!AJ40=""),"",'Haq — Monthly P&L and cash'!Q5='Model inputs'!AJ40))="",FALSE,IF(ISERROR('Haq — Monthly P&L and cash'!Q5='Model inputs'!AJ40),'Haq — Monthly P&L and cash'!Q5='Model inputs'!AJ40,IF(OR('Haq — Monthly P&L and cash'!Q5="",'Model inputs'!AJ40=""),"",'Haq — Monthly P&L and cash'!Q5='Model inputs'!AJ40))),IF('Model inputs'!AJ41="","",'Model inputs'!AJ41),'Haq — Monthly P&L and cash'!P7*(1+'Model inputs'!AJ37-'Model inputs'!AJ42))) -> 267.51251 | R7: =IF(IF(IF(ISERROR('Haq — Monthly P&L and cash'!R5<'Model inputs'!AJ40),'Haq — Monthly P&L and cash'!R5<'Model inputs'!AJ40,IF(OR('Haq — Monthly P&L and cash'!R5="",'Model inputs'!AJ40=""),"",'Haq — Monthly P&L and cash'!R5<'Model inputs'!AJ40))="",FALSE,IF(ISERROR('Haq — Monthly P&L and cash'!R5<'Model inputs'!AJ40),'Haq — Monthly P&L and cash'!R5<'Model inputs'!AJ40,IF(OR('Haq — Monthly P&L and cash'!R5="",'Model inputs'!AJ40=""),"",'Haq — Monthly P&L and cash'!R5<'Model inputs'!AJ40))),0,IF(IF(IF(ISERROR('Haq — Monthly P&L and cash'!R5='Model inputs'!AJ40),'Haq — Monthly P&L and cash'!R5='Model inputs'!AJ40,IF(OR('Haq — Monthly P&L and cash'!R5="",'Model inputs'!AJ40=""),"",'Haq — Monthly P&L and cash'!R5='Model inputs'!AJ40))="",FALSE,IF(ISERROR('Haq — Monthly P&L and cash'!R5='Model inputs'!AJ40),'Haq — Monthly P&L and cash'!R5='Model inputs'!AJ40,IF(OR('Haq — Monthly P&L and cash'!R5="",'Model inputs'!AJ40=""),"",'Haq — Monthly P&L and cash'!R5='Model inputs'!AJ40))),IF('Model inputs'!AJ41="","",'Model inputs'!AJ41),'Haq — Monthly P&L and cash'!Q7*(1+'Model inputs'!AJ37-'Model inputs'!AJ42))) -> 307.63938 | S7: =IF(IF(IF(ISERROR('Haq — Monthly P&L and cash'!S5<'Model inputs'!AJ40),'Haq — Monthly P&L and cash'!S5<'Model inputs'!AJ40,IF(OR('Haq — Monthly P&L and cash'!S5="",'Model inputs'!AJ40=""),"",'Haq — Monthly P&L and cash'!S5<'Model inputs'!AJ40))="",FALSE,IF(ISERROR('Haq — Monthly P&L and cash'!S5<'Model inputs'!AJ40),'Haq — Monthly P&L and cash'!S5<'Model inputs'!AJ40,IF(OR('Haq — Monthly P&L and cash'!S5="",'Model inputs'!AJ40=""),"",'Haq — Monthly P&L and cash'!S5<'Model inputs'!AJ40))),0,IF(IF(IF(ISERROR('Haq — Monthly P&L and cash'!S5='Model inputs'!AJ40),'Haq — Monthly P&L and cash'!S5='Model inputs'!AJ40,IF(OR('Haq — Monthly P&L and cash'!S5="",'Model inputs'!AJ40=""),"",'Haq — Monthly P&L and cash'!S5='Model inputs'!AJ40))="",FALSE,IF(ISERROR('Haq — Monthly P&L and cash'!S5='Model inputs'!AJ40),'Haq — Monthly P&L and cash'!S5='Model inputs'!AJ40,IF(OR('Haq — Monthly P&L and cash'!S5="",'Model inputs'!AJ40=""),"",'Haq — Monthly P&L and cash'!S5='Model inputs'!AJ40))),IF('Model inputs'!AJ41="","",'Model inputs'!AJ41),'Haq — Monthly P&L and cash'!R7*(1+'Model inputs'!AJ37-'Model inputs'!AJ42))) -> 353.78529 | T7: =IF(IF(IF(ISERROR('Haq — Monthly P&L and cash'!T5<'Model inputs'!AJ40),'Haq — Monthly P&L and cash'!T5<'Model inputs'!AJ40,IF(OR('Haq — Monthly P&L and cash'!T5="",'Model inputs'!AJ40=""),"",'Haq — Monthly P&L and cash'!T5<'Model inputs'!AJ40))="",FALSE,IF(ISERROR('Haq — Monthly P&L and cash'!T5<'Model inputs'!AJ40),'Haq — Monthly P&L and cash'!T5<'Model inputs'!AJ40,IF(OR('Haq — Monthly P&L and cash'!T5="",'Model inputs'!AJ40=""),"",'Haq — Monthly P&L and cash'!T5<'Model inputs'!AJ40))),0,IF(IF(IF(ISERROR('Haq — Monthly P&L and cash'!T5='Model inputs'!AJ40),'Haq — Monthly P&L and cash'!T5='Model inputs'!AJ40,IF(OR('Haq — Monthly P&L and cash'!T5="",'Model inputs'!AJ40=""),"",'Haq — Monthly P&L and cash'!T5='Model inputs'!AJ40))="",FALSE,IF(ISERROR('Haq — Monthly P&L and cash'!T5='Model inputs'!AJ40),'Haq — Monthly P&L and cash'!T5='Model inputs'!AJ40,IF(OR('Haq — Monthly P&L and cash'!T5="",'Model inputs'!AJ40=""),"",'Haq — Monthly P&L and cash'!T5='Model inputs'!AJ40))),IF('Model inputs'!AJ41="","",'Model inputs'!AJ41),'Haq — Monthly P&L and cash'!S7*(1+'Model inputs'!AJ37-'Model inputs'!AJ42))) -> 406.85308 | U7: =IF(IF(IF(ISERROR('Haq — Monthly P&L and cash'!U5<'Model inputs'!AJ40),'Haq — Monthly P&L and cash'!U5<'Model inputs'!AJ40,IF(OR('Haq — Monthly P&L and cash'!U5="",'Model inputs'!AJ40=""),"",'Haq — Monthly P&L and cash'!U5<'Model inputs'!AJ40))="",FALSE,IF(ISERROR('Haq — Monthly P&L and cash'!U5<'Model inputs'!AJ40),'Haq — Monthly P&L and cash'!U5<'Model inputs'!AJ40,IF(OR('Haq — Monthly P&L and cash'!U5="",'Model inputs'!AJ40=""),"",'Haq — Monthly P&L and cash'!U5<'Model inputs'!AJ40))),0,IF(IF(IF(ISERROR('Haq — Monthly P&L and cash'!U5='Model inputs'!AJ40),'Haq — Monthly P&L and cash'!U5='Model inputs'!AJ40,IF(OR('Haq — Monthly P&L and cash'!U5="",'Model inputs'!AJ40=""),"",'Haq — Monthly P&L and cash'!U5='Model inputs'!AJ40))="",FALSE,IF(ISERROR('Haq — Monthly P&L and cash'!U5='Model inputs'!AJ40),'Haq — Monthly P&L and cash'!U5='Model inputs'!AJ40,IF(OR('Haq — Monthly P&L and cash'!U5="",'Model inputs'!AJ40=""),"",'Haq — Monthly P&L and cash'!U5='Model inputs'!AJ40))),IF('Model inputs'!AJ41="","",'Model inputs'!AJ41),'Haq — Monthly P&L and cash'!T7*(1+'Model inputs'!AJ37-'Model inputs'!AJ42))) -> 467.88104 | V7: =IF(IF(IF(ISERROR('Haq — Monthly P&L and cash'!V5<'Model inputs'!AJ40),'Haq — Monthly P&L and cash'!V5<'Model inputs'!AJ40,IF(OR('Haq — Monthly P&L and cash'!V5="",'Model inputs'!AJ40=""),"",'Haq — Monthly P&L and cash'!V5<'Model inputs'!AJ40))="",FALSE,IF(ISERROR('Haq — Monthly P&L and cash'!V5<'Model inputs'!AJ40),'Haq — Monthly P&L and cash'!V5<'Model inputs'!AJ40,IF(OR('Haq — Monthly P&L and cash'!V5="",'Model inputs'!AJ40=""),"",'Haq — Monthly P&L and cash'!V5<'Model inputs'!AJ40))),0,IF(IF(IF(ISERROR('Haq — Monthly P&L and cash'!V5='Model inputs'!AJ40),'Haq — Monthly P&L and cash'!V5='Model inputs'!AJ40,IF(OR('Haq — Monthly P&L and cash'!V5="",'Model inputs'!AJ40=""),"",'Haq — Monthly P&L and cash'!V5='Model inputs'!AJ40))="",FALSE,IF(ISERROR('Haq — Monthly P&L and cash'!V5='Model inputs'!AJ40),'Haq — Monthly P&L and cash'!V5='Model inputs'!AJ40,IF(OR('Haq — Monthly P&L and cash'!V5="",'Model inputs'!AJ40=""),"",'Haq — Monthly P&L and cash'!V5='Model inputs'!AJ40))),IF('Model inputs'!AJ41="","",'Model inputs'!AJ41),'Haq — Monthly P&L and cash'!U7*(1+'Model inputs'!AJ37-'Model inputs'!AJ42))) -> 538.0632 | W7: =IF(IF(IF(ISERROR('Haq — Monthly P&L and cash'!W5<'Model inputs'!AJ40),'Haq — Monthly P&L and cash'!W5<'Model inputs'!AJ40,IF(OR('Haq — Monthly P&L and cash'!W5="",'Model inputs'!AJ40=""),"",'Haq — Monthly P&L and cash'!W5<'Model inputs'!AJ40))="",FALSE,IF(ISERROR('Haq — Monthly P&L and cash'!W5<'Model inputs'!AJ40),'Haq — Monthly P&L and cash'!W5<'Model inputs'!AJ40,IF(OR('Haq — Monthly P&L and cash'!W5="",'Model inputs'!AJ40=""),"",'Haq — Monthly P&L and cash'!W5<'Model inputs'!AJ40))),0,IF(IF(IF(ISERROR('Haq — Monthly P&L and cash'!W5='Model inputs'!AJ40),'Haq — Monthly P&L and cash'!W5='Model inputs'!AJ40,IF(OR('Haq — Monthly P&L and cash'!W5="",'Model inputs'!AJ40=""),"",'Haq — Monthly P&L and cash'!W5='Model inputs'!AJ40))="",FALSE,IF(ISERROR('Haq — Monthly P&L and cash'!W5='Model inputs'!AJ40),'Haq — Monthly P&L and cash'!W5='Model inputs'!AJ40,IF(OR('Haq — Monthly P&L and cash'!W5="",'Model inputs'!AJ40=""),"",'Haq — Monthly P&L and cash'!W5='Model inputs'!AJ40))),IF('Model inputs'!AJ41="","",'Model inputs'!AJ41),'Haq — Monthly P&L and cash'!V7*(1+'Model inputs'!AJ37-'Model inputs'!AJ42))) -> 618.77268 | X7: =IF(IF(IF(ISERROR('Haq — Monthly P&L and cash'!X5<'Model inputs'!AJ40),'Haq — Monthly P&L and cash'!X5<'Model inputs'!AJ40,IF(OR('Haq — Monthly P&L and cash'!X5="",'Model inputs'!AJ40=""),"",'Haq — Monthly P&L and cash'!X5<'Model inputs'!AJ40))="",FALSE,IF(ISERROR('Haq — Monthly P&L and cash'!X5<'Model inputs'!AJ40),'Haq — Monthly P&L and cash'!X5<'Model inputs'!AJ40,IF(OR('Haq — Monthly P&L and cash'!X5="",'Model inputs'!AJ40=""),"",'Haq — Monthly P&L and cash'!X5<'Model inputs'!AJ40))),0,IF(IF(IF(ISERROR('Haq — Monthly P&L and cash'!X5='Model inputs'!AJ40),'Haq — Monthly P&L and cash'!X5='Model inputs'!AJ40,IF(OR('Haq — Monthly P&L and cash'!X5="",'Model inputs'!AJ40=""),"",'Haq — Monthly P&L and cash'!X5='Model inputs'!AJ40))="",FALSE,IF(ISERROR('Haq — Monthly P&L and cash'!X5='Model inputs'!AJ40),'Haq — Monthly P&L and cash'!X5='Model inputs'!AJ40,IF(OR('Haq — Monthly P&L and cash'!X5="",'Model inputs'!AJ40=""),"",'Haq — Monthly P&L and cash'!X5='Model inputs'!AJ40))),IF('Model inputs'!AJ41="","",'Model inputs'!AJ41),'Haq — Monthly P&L and cash'!W7*(1+'Model inputs'!AJ37-'Model inputs'!AJ42))) -> 711.58858 | Y7: =IF(IF(IF(ISERROR('Haq — Monthly P&L and cash'!Y5<'Model inputs'!AJ40),'Haq — Monthly P&L and cash'!Y5<'Model inputs'!AJ40,IF(OR('Haq — Monthly P&L and cash'!Y5="",'Model inputs'!AJ40=""),"",'Haq — Monthly P&L and cash'!Y5<'Model inputs'!AJ40))="",FALSE,IF(ISERROR('Haq — Monthly P&L and cash'!Y5<'Model inputs'!AJ40),'Haq — Monthly P&L and cash'!Y5<'Model inputs'!AJ40,IF(OR('Haq — Monthly P&L and cash'!Y5="",'Model inputs'!AJ40=""),"",'Haq — Monthly P&L and cash'!Y5<'Model inputs'!AJ40))),0,IF(IF(IF(ISERROR('Haq — Monthly P&L and cash'!Y5='Model inputs'!AJ40),'Haq — Monthly P&L and cash'!Y5='Model inputs'!AJ40,IF(OR('Haq — Monthly P&L and cash'!Y5="",'Model inputs'!AJ40=""),"",'Haq — Monthly P&L and cash'!Y5='Model inputs'!AJ40))="",FALSE,IF(ISERROR('Haq — Monthly P&L and cash'!Y5='Model inputs'!AJ40),'Haq — Monthly P&L and cash'!Y5='Model inputs'!AJ40,IF(OR('Haq — Monthly P&L and cash'!Y5="",'Model inputs'!AJ40=""),"",'Haq — Monthly P&L and cash'!Y5='Model inputs'!AJ40))),IF('Model inputs'!AJ41="","",'Model inputs'!AJ41),'Haq — Monthly P&L and cash'!X7*(1+'Model inputs'!AJ37-'Model inputs'!AJ42))) -> 818.32687
